Workbook

Sheet Les meg
B1: Reisekalender – beste tid for reisemål
B2: Mock-up. Masterliste = «Reise - utenfor Europa.md». Klimatall er omtrentlige og verifiseres ved populering.
B4: Flyt
B5: 1. Destinasjoner – én rad per reisemål (fra .md-filen). ID brukes som nøkkel i alle andre ark.
B6: 2. Måned – 12 rader per destinasjon med delscorer, T/N og begrunnelse. Samlet score beregnes.
B7: 3. Vinduer – ukesavgrensede justeringer (hendelser, dyreliv, helligdager). Legges oppå månedsscoren.
B8: 4. Kalender – generert heatmap destinasjon × ISO-uke. Marker egne tilgjengelige uker med «x» i rad 7.
B10: Konvensjoner
B11: Blå tekst / gul bakgrunn = input. Svart = formel. Ikke skriv i formelceller.
B12: Uke → måned: en uke tilhører måneden torsdagen faller i (ISO-logikk). Uke 53 (f.eks. 2026) vises ikke.
B13: Vindu med Fra > Til går over nyttår (f.eks. uke 49–12).
B15: Scoreskala (1–5)
... B20: Vekter for samlet score
B21: Klima | C21: 0.4
B22: Opplevelse | C22: 0.4
B23: Trengsel/pris | C23: 0.2
B24: Sum (skal være 100 %) | C24: =SUM(C21:C23)
B25: Veto-tak: Hvis Klima eller Opplevelse = 1, begrenses samlet score til dette taket (vektet snitt hvis lavere). | C25: 1.5
B26: Vindu-justering (±) legges til i Kalender; resultatet begrenses til 1–5.

Sheet Kalender
A1: Kalender – score per ISO-uke
A2: År | B2: 2026 | C2: Månedsscore + vinduer, begrenset til 1–5. Tomt = ikke vurdert ennå.
A3: Grønn fra | B3: 4 | C3: Uker med score ≥ denne verdien farges lysegrønne; resten er uten farge.
A4: Mørkegrønn fra | B4: 4.4 | C4: De beste ukene (score ≥ denne verdien) farges mørkegrønne. | E4: Uke | F4: 1 | G4: 2 | H4: 3 | I4: 4 | J4: 5 | K4: 6 | L4: 7 | M4: 8 | N4: 9 | O4: 10 | P4: 11 | Q4: 12 | R4: 13 | S4: 14 | T4: 15 | U4: 16 | V4: 17 | W4: 18 | X4: 19 | Y4: 20 | Z4: 21 | AA4: 22 | AB4: 23 | AC4: 24 | AD4: 25 | AE4: 26 | AF4: 27 | AG4: 28 | AH4: 29 | AI4: 30 | AJ4: 31 | AK4: 32 | AL4: 33 | AM4: 34 | AN4: 35 | AO4: 36 | AP4: 37 | AQ4: 38 | AR4: 39 | AS4: 40 | AT4: 41 | AU4: 42 | AV4: 43 | AW4: 44 | AX4: 45 | AY4: 46 | AZ4: 47 | BA4: 48 | BB4: 49 | BC4: 50 | BD4: 51 | BE4: 52
E5: Mandag | F5: =DATE($B$2,1,4)-WEEKDAY(DATE($B$2,1,4),2)+1+(F4-1)*7 | G5: =DATE($B$2,1,4)-WEEKDAY(DATE($B$2,1,4),2)+1+(G4-1)*7 | H5: =DATE($B$2,1,4)-WEEKDAY(DATE($B$2,1,4),2)+1+(H4-1)*7 | I5: =DATE($B$2,1,4)-WEEKDAY(DATE($B$2,1,4),2)+1+(I4-1)*7 | J5: =DATE($B$2,1,4)-WEEKDAY(DATE($B$2,1,4),2)+1+(J4-1)*7 | K5: =DATE($B$2,1,4)-WEEKDAY(DATE($B$2,1,4),2)+1+(K4-1)*7 | L5: =DATE($B$2,1,4)-WEEKDAY(DATE($B$2,1,4),2)+1+(L4-1)*7 | M5: =DATE($B$2,1,4)-WEEKDAY(DATE($B$2,1,4),2)+1+(M4-1)*7 | ... BE5: =DATE($B$2,1,4)-WEEKDAY(DATE($B$2,1,4),2)+1+(BE4-1)*7
E6: Måned | F6: =CHOOSE(MONTH(F5+3),"jan","feb","mar","apr","mai","jun","jul","aug","sep","okt","nov","des") | G6: =IF(MONTH(G5+3)<>MONTH(F5+3),CHOOSE(MONTH(G5+3),"jan","feb","mar","apr","mai","jun","jul","aug","sep","okt","nov","des"),"") | H6: =IF(MONTH(H5+3)<>MONTH(G5+3),CHOOSE(MONTH(H5+3),"jan","feb","mar","apr","mai","jun","jul","aug","sep","okt","nov","des"),"") | I6: =IF(MONTH(I5+3)<>MONTH(H5+3),CHOOSE(MONTH(I5+3),"jan","feb","mar","apr","mai","jun","jul","aug","sep","okt","nov","des"),"") | J6: =IF(MONTH(J5+3)<>MONTH(I5+3),CHOOSE(MONTH(J5+3),"jan","feb","mar","apr","mai","jun","jul","aug","sep","okt","nov","des"),"") | K6: =IF(MONTH(K5+3)<>MONTH(J5+3),CHOOSE(MONTH(K5+3),"jan","feb","mar","apr","mai","jun","jul","aug","sep","okt","nov","des"),"") | L6: =IF(MONTH(L5+3)<>MONTH(K5+3),CHOOSE(MONTH(L5+3),"jan","feb","mar","apr","mai","jun","jul","aug","sep","okt","nov","des"),"") | M6: =IF(MONTH(M5+3)<>MONTH(L5+3),CHOOSE(MONTH(M5+3),"jan","feb","mar","apr","mai","jun","jul","aug","sep","okt","nov","des"),"") | N6: =IF(MONTH(N5+3)<>MONTH(M5+3),CHOOSE(MONTH(N5+3),"jan","feb","mar","apr","mai","jun","jul","aug","sep","okt","nov","des"),"") | ... BE6: =IF(MONTH(BE5+3)<>MONTH(BD5+3),CHOOSE(MONTH(BE5+3),"jan","feb","mar","apr","mai","jun","jul","aug","sep","okt","nov","des"),"")
E7: Tilgjengelig (x) | AX7: x | AY7: x | AZ7: x | BA7: x
A8: ID | B8: Destinasjon | C8: Region | D8: Snitt mine uker | E8: Laveste mine uker
A9: =IF(Destinasjoner!A5="","",Destinasjoner!A5) | B9: =IF(A9="","",Destinasjoner!E5) | C9: =IF(A9="","",Destinasjoner!B5) | D9: =IFERROR(SUMIFS(F9:BE9,$F$7:$BE$7,"x")/COUNTIFS($F$7:$BE$7,"x",F9:BE9,">0"),"") | E9: =IF(D9="","",_xlfn.MINIFS(F9:BE9,$F$7:$BE$7,"x",F9:BE9,">0")) | F9: =IF($A9="","",IF(COUNTIFS(Måned!$A$5:$A$2000,$A9,Måned!$C$5:$C$2000,MONTH(F$5+3))=0,"",MAX(1,MIN(5,SUMIFS(Måned!$H$5:$H$2000,Måned!$A$5:$A$2000,$A9,Måned!$C$5:$C$2000,MONTH(F$5+3))+SUMPRODUCT((Vinduer!$A$5:$A$300=$A9)*Vinduer!$F$5:$F$300*(((Vinduer!$G$5:$G$300="")+(Vinduer!$G$5:$G$300=$B$2))>0)*((Vinduer!$C$5:$C$300<=Vinduer!$D$5:$D$300)*(F$4>=Vinduer!$C$5:$C$300)*(F$4<=Vinduer!$D$5:$D$300)+(Vinduer!$C$5:$C$300>Vinduer!$D$5:$D$300)*(((F$4>=Vinduer!$C$5:$C$300)+(F$4<=Vinduer!$D$5:$D$300))>0))))))) | G9: =IF($A9="","",IF(COUNTIFS(Måned!$A$5:$A$2000,$A9,Måned!$C$5:$C$2000,MONTH(G$5+3))=0,"",MAX(1,MIN(5,SUMIFS(Måned!$H$5:$H$2000,Måned!$A$5:$A$2000,$A9,Måned!$C$5:$C$2000,MONTH(G$5+3))+SUMPRODUCT((Vinduer!$A$5:$A$300=$A9)*Vinduer!$F$5:$F$300*(((Vinduer!$G$5:$G$300="")+(Vinduer!$G$5:$G$300=$B$2))>0)*((Vinduer!$C$5:$C$300<=Vinduer!$D$5:$D$300)*(G$4>=Vinduer!$C$5:$C$300)*(G$4<=Vinduer!$D$5:$D$300)+(Vinduer!$C$5:$C$300>Vinduer!$D$5:$D$300)*(((G$4>=Vinduer!$C$5:$C$300)+(G$4<=Vinduer!$D$5:$D$300))>0))))))) | H9: =IF($A9="","",IF(COUNTIFS(Måned!$A$5:$A$2000,$A9,Måned!$C$5:$C$2000,MONTH(H$5+3))=0,"",MAX(1,MIN(5,SUMIFS(Måned!$H$5:$H$2000,Måned!$A$5:$A$2000,$A9,Måned!$C$5:$C$2000,MONTH(H$5+3))+SUMPRODUCT((Vinduer!$A$5:$A$300=$A9)*Vinduer!$F$5:$F$300*(((Vinduer!$G$5:$G$300="")+(Vinduer!$G$5:$G$300=$B$2))>0)*((Vinduer!$C$5:$C$300<=Vinduer!$D$5:$D$300)*(H$4>=Vinduer!$C$5:$C$300)*(H$4<=Vinduer!$D$5:$D$300)+(Vinduer!$C$5:$C$300>Vinduer!$D$5:$D$300)*(((H$4>=Vinduer!$C$5:$C$300)+(H$4<=Vinduer!$D$5:$D$300))>0))))))) | I9: =IF($A9="","",IF(COUNTIFS(Måned!$A$5:$A$2000,$A9,Måned!$C$5:$C$2000,MONTH(I$5+3))=0,"",MAX(1,MIN(5,SUMIFS(Måned!$H$5:$H$2000,Måned!$A$5:$A$2000,$A9,Måned!$C$5:$C$2000,MONTH(I$5+3))+SUMPRODUCT((Vinduer!$A$5:$A$300=$A9)*Vinduer!$F$5:$F$300*(((Vinduer!$G$5:$G$300="")+(Vinduer!$G$5:$G$300=$B$2))>0)*((Vinduer!$C$5:$C$300<=Vinduer!$D$5:$D$300)*(I$4>=Vinduer!$C$5:$C$300)*(I$4<=Vinduer!$D$5:$D$300)+(Vinduer!$C$5:$C$300>Vinduer!$D$5:$D$300)*(((I$4>=Vinduer!$C$5:$C$300)+(I$4<=Vinduer!$D$5:$D$300))>0))))))) | J9: =IF($A9="","",IF(COUNTIFS(Måned!$A$5:$A$2000,$A9,Måned!$C$5:$C$2000,MONTH(J$5+3))=0,"",MAX(1,MIN(5,SUMIFS(Måned!$H$5:$H$2000,Måned!$A$5:$A$2000,$A9,Måned!$C$5:$C$2000,MONTH(J$5+3))+SUMPRODUCT((Vinduer!$A$5:$A$300=$A9)*Vinduer!$F$5:$F$300*(((Vinduer!$G$5:$G$300="")+(Vinduer!$G$5:$G$300=$B$2))>0)*((Vinduer!$C$5:$C$300<=Vinduer!$D$5:$D$300)*(J$4>=Vinduer!$C$5:$C$300)*(J$4<=Vinduer!$D$5:$D$300)+(Vinduer!$C$5:$C$300>Vinduer!$D$5:$D$300)*(((J$4>=Vinduer!$C$5:$C$300)+(J$4<=Vinduer!$D$5:$D$300))>0))))))) | K9: =IF($A9="","",IF(COUNTIFS(Måned!$A$5:$A$2000,$A9,Måned!$C$5:$C$2000,MONTH(K$5+3))=0,"",MAX(1,MIN(5,SUMIFS(Måned!$H$5:$H$2000,Måned!$A$5:$A$2000,$A9,Måned!$C$5:$C$2000,MONTH(K$5+3))+SUMPRODUCT((Vinduer!$A$5:$A$300=$A9)*Vinduer!$F$5:$F$300*(((Vinduer!$G$5:$G$300="")+(Vinduer!$G$5:$G$300=$B$2))>0)*((Vinduer!$C$5:$C$300<=Vinduer!$D$5:$D$300)*(K$4>=Vinduer!$C$5:$C$300)*(K$4<=Vinduer!$D$5:$D$300)+(Vinduer!$C$5:$C$300>Vinduer!$D$5:$D$300)*(((K$4>=Vinduer!$C$5:$C$300)+(K$4<=Vinduer!$D$5:$D$300))>0))))))) | L9: =IF($A9="","",IF(COUNTIFS(Måned!$A$5:$A$2000,$A9,Måned!$C$5:$C$2000,MONTH(L$5+3))=0,"",MAX(1,MIN(5,SUMIFS(Måned!$H$5:$H$2000,Måned!$A$5:$A$2000,$A9,Måned!$C$5:$C$2000,MONTH(L$5+3))+SUMPRODUCT((Vinduer!$A$5:$A$300=$A9)*Vinduer!$F$5:$F$300*(((Vinduer!$G$5:$G$300="")+(Vinduer!$G$5:$G$300=$B$2))>0)*((Vinduer!$C$5:$C$300<=Vinduer!$D$5:$D$300)*(L$4>=Vinduer!$C$5:$C$300)*(L$4<=Vinduer!$D$5:$D$300)+(Vinduer!$C$5:$C$300>Vinduer!$D$5:$D$300)*(((L$4>=Vinduer!$C$5:$C$300)+(L$4<=Vinduer!$D$5:$D$300))>0))))))) | M9: =IF($A9="","",IF(COUNTIFS(Måned!$A$5:$A$2000,$A9,Måned!$C$5:$C$2000,MONTH(M$5+3))=0,"",MAX(1,MIN(5,SUMIFS(Måned!$H$5:$H$2000,Måned!$A$5:$A$2000,$A9,Måned!$C$5:$C$2000,MONTH(M$5+3))+SUMPRODUCT((Vinduer!$A$5:$A$300=$A9)*Vinduer!$F$5:$F$300*(((Vinduer!$G$5:$G$300="")+(Vinduer!$G$5:$G$300=$B$2))>0)*((Vinduer!$C$5:$C$300<=Vinduer!$D$5:$D$300)*(M$4>=Vinduer!$C$5:$C$300)*(M$4<=Vinduer!$D$5:$D$300)+(Vinduer!$C$5:$C$300>Vinduer!$D$5:$D$300)*(((M$4>=Vinduer!$C$5:$C$300)+(M$4<=Vinduer!$D$5:$D$300))>0))))))) | ... BE9: =IF($A9="","",IF(COUNTIFS(Måned!$A$5:$A$2000,$A9,Måned!$C$5:$C$2000,MONTH(BE$5+3))=0,"",MAX(1,MIN(5,SUMIFS(Måned!$H$5:$H$2000,Måned!$A$5:$A$2000,$A9,Måned!$C$5:$C$2000,MONTH(BE$5+3))+SUMPRODUCT((Vinduer!$A$5:$A$300=$A9)*Vinduer!$F$5:$F$300*(((Vinduer!$G$5:$G$300="")+(Vinduer!$G$5:$G$300=$B$2))>0)*((Vinduer!$C$5:$C$300<=Vinduer!$D$5:$D$300)*(BE$4>=Vinduer!$C$5:$C$300)*(BE$4<=Vinduer!$D$5:$D$300)+(Vinduer!$C$5:$C$300>Vinduer!$D$5:$D$300)*(((BE$4>=Vinduer!$C$5:$C$300)+(BE$4<=Vinduer!$D$5:$D$300))>0)))))))
A10: =IF(Destinasjoner!A6="","",Destinasjoner!A6) | B10: =IF(A10="","",Destinasjoner!E6) | C10: =IF(A10="","",Destinasjoner!B6) | D10: =IFERROR(SUMIFS(F10:BE10,$F$7:$BE$7,"x")/COUNTIFS($F$7:$BE$7,"x",F10:BE10,">0"),"") | E10: =IF(D10="","",_xlfn.MINIFS(F10:BE10,$F$7:$BE$7,"x",F10:BE10,">0")) | F10: =IF($A10="","",IF(COUNTIFS(Måned!$A$5:$A$2000,$A10,Måned!$C$5:$C$2000,MONTH(F$5+3))=0,"",MAX(1,MIN(5,SUMIFS(Måned!$H$5:$H$2000,Måned!$A$5:$A$2000,$A10,Måned!$C$5:$C$2000,MONTH(F$5+3))+SUMPRODUCT((Vinduer!$A$5:$A$300=$A10)*Vinduer!$F$5:$F$300*(((Vinduer!$G$5:$G$300="")+(Vinduer!$G$5:$G$300=$B$2))>0)*((Vinduer!$C$5:$C$300<=Vinduer!$D$5:$D$300)*(F$4>=Vinduer!$C$5:$C$300)*(F$4<=Vinduer!$D$5:$D$300)+(Vinduer!$C$5:$C$300>Vinduer!$D$5:$D$300)*(((F$4>=Vinduer!$C$5:$C$300)+(F$4<=Vinduer!$D$5:$D$300))>0))))))) | G10: =IF($A10="","",IF(COUNTIFS(Måned!$A$5:$A$2000,$A10,Måned!$C$5:$C$2000,MONTH(G$5+3))=0,"",MAX(1,MIN(5,SUMIFS(Måned!$H$5:$H$2000,Måned!$A$5:$A$2000,$A10,Måned!$C$5:$C$2000,MONTH(G$5+3))+SUMPRODUCT((Vinduer!$A$5:$A$300=$A10)*Vinduer!$F$5:$F$300*(((Vinduer!$G$5:$G$300="")+(Vinduer!$G$5:$G$300=$B$2))>0)*((Vinduer!$C$5:$C$300<=Vinduer!$D$5:$D$300)*(G$4>=Vinduer!$C$5:$C$300)*(G$4<=Vinduer!$D$5:$D$300)+(Vinduer!$C$5:$C$300>Vinduer!$D$5:$D$300)*(((G$4>=Vinduer!$C$5:$C$300)+(G$4<=Vinduer!$D$5:$D$300))>0))))))) | H10: =IF($A10="","",IF(COUNTIFS(Måned!$A$5:$A$2000,$A10,Måned!$C$5:$C$2000,MONTH(H$5+3))=0,"",MAX(1,MIN(5,SUMIFS(Måned!$H$5:$H$2000,Måned!$A$5:$A$2000,$A10,Måned!$C$5:$C$2000,MONTH(H$5+3))+SUMPRODUCT((Vinduer!$A$5:$A$300=$A10)*Vinduer!$F$5:$F$300*(((Vinduer!$G$5:$G$300="")+(Vinduer!$G$5:$G$300=$B$2))>0)*((Vinduer!$C$5:$C$300<=Vinduer!$D$5:$D$300)*(H$4>=Vinduer!$C$5:$C$300)*(H$4<=Vinduer!$D$5:$D$300)+(Vinduer!$C$5:$C$300>Vinduer!$D$5:$D$300)*(((H$4>=Vinduer!$C$5:$C$300)+(H$4<=Vinduer!$D$5:$D$300))>0))))))) | I10: =IF($A10="","",IF(COUNTIFS(Måned!$A$5:$A$2000,$A10,Måned!$C$5:$C$2000,MONTH(I$5+3))=0,"",MAX(1,MIN(5,SUMIFS(Måned!$H$5:$H$2000,Måned!$A$5:$A$2000,$A10,Måned!$C$5:$C$2000,MONTH(I$5+3))+SUMPRODUCT((Vinduer!$A$5:$A$300=$A10)*Vinduer!$F$5:$F$300*(((Vinduer!$G$5:$G$300="")+(Vinduer!$G$5:$G$300=$B$2))>0)*((Vinduer!$C$5:$C$300<=Vinduer!$D$5:$D$300)*(I$4>=Vinduer!$C$5:$C$300)*(I$4<=Vinduer!$D$5:$D$300)+(Vinduer!$C$5:$C$300>Vinduer!$D$5:$D$300)*(((I$4>=Vinduer!$C$5:$C$300)+(I$4<=Vinduer!$D$5:$D$300))>0))))))) | J10: =IF($A10="","",IF(COUNTIFS(Måned!$A$5:$A$2000,$A10,Måned!$C$5:$C$2000,MONTH(J$5+3))=0,"",MAX(1,MIN(5,SUMIFS(Måned!$H$5:$H$2000,Måned!$A$5:$A$2000,$A10,Måned!$C$5:$C$2000,MONTH(J$5+3))+SUMPRODUCT((Vinduer!$A$5:$A$300=$A10)*Vinduer!$F$5:$F$300*(((Vinduer!$G$5:$G$300="")+(Vinduer!$G$5:$G$300=$B$2))>0)*((Vinduer!$C$5:$C$300<=Vinduer!$D$5:$D$300)*(J$4>=Vinduer!$C$5:$C$300)*(J$4<=Vinduer!$D$5:$D$300)+(Vinduer!$C$5:$C$300>Vinduer!$D$5:$D$300)*(((J$4>=Vinduer!$C$5:$C$300)+(J$4<=Vinduer!$D$5:$D$300))>0))))))) | K10: =IF($A10="","",IF(COUNTIFS(Måned!$A$5:$A$2000,$A10,Måned!$C$5:$C$2000,MONTH(K$5+3))=0,"",MAX(1,MIN(5,SUMIFS(Måned!$H$5:$H$2000,Måned!$A$5:$A$2000,$A10,Måned!$C$5:$C$2000,MONTH(K$5+3))+SUMPRODUCT((Vinduer!$A$5:$A$300=$A10)*Vinduer!$F$5:$F$300*(((Vinduer!$G$5:$G$300="")+(Vinduer!$G$5:$G$300=$B$2))>0)*((Vinduer!$C$5:$C$300<=Vinduer!$D$5:$D$300)*(K$4>=Vinduer!$C$5:$C$300)*(K$4<=Vinduer!$D$5:$D$300)+(Vinduer!$C$5:$C$300>Vinduer!$D$5:$D$300)*(((K$4>=Vinduer!$C$5:$C$300)+(K$4<=Vinduer!$D$5:$D$300))>0))))))) | L10: =IF($A10="","",IF(COUNTIFS(Måned!$A$5:$A$2000,$A10,Måned!$C$5:$C$2000,MONTH(L$5+3))=0,"",MAX(1,MIN(5,SUMIFS(Måned!$H$5:$H$2000,Måned!$A$5:$A$2000,$A10,Måned!$C$5:$C$2000,MONTH(L$5+3))+SUMPRODUCT((Vinduer!$A$5:$A$300=$A10)*Vinduer!$F$5:$F$300*(((Vinduer!$G$5:$G$300="")+(Vinduer!$G$5:$G$300=$B$2))>0)*((Vinduer!$C$5:$C$300<=Vinduer!$D$5:$D$300)*(L$4>=Vinduer!$C$5:$C$300)*(L$4<=Vinduer!$D$5:$D$300)+(Vinduer!$C$5:$C$300>Vinduer!$D$5:$D$300)*(((L$4>=Vinduer!$C$5:$C$300)+(L$4<=Vinduer!$D$5:$D$300))>0))))))) | M10: =IF($A10="","",IF(COUNTIFS(Måned!$A$5:$A$2000,$A10,Måned!$C$5:$C$2000,MONTH(M$5+3))=0,"",MAX(1,MIN(5,SUMIFS(Måned!$H$5:$H$2000,Måned!$A$5:$A$2000,$A10,Måned!$C$5:$C$2000,MONTH(M$5+3))+SUMPRODUCT((Vinduer!$A$5:$A$300=$A10)*Vinduer!$F$5:$F$300*(((Vinduer!$G$5:$G$300="")+(Vinduer!$G$5:$G$300=$B$2))>0)*((Vinduer!$C$5:$C$300<=Vinduer!$D$5:$D$300)*(M$4>=Vinduer!$C$5:$C$300)*(M$4<=Vinduer!$D$5:$D$300)+(Vinduer!$C$5:$C$300>Vinduer!$D$5:$D$300)*(((M$4>=Vinduer!$C$5:$C$300)+(M$4<=Vinduer!$D$5:$D$300))>0))))))) | ... BE10: =IF($A10="","",IF(COUNTIFS(Måned!$A$5:$A$2000,$A10,Måned!$C$5:$C$2000,MONTH(BE$5+3))=0,"",MAX(1,MIN(5,SUMIFS(Måned!$H$5:$H$2000,Måned!$A$5:$A$2000,$A10,Måned!$C$5:$C$2000,MONTH(BE$5+3))+SUMPRODUCT((Vinduer!$A$5:$A$300=$A10)*Vinduer!$F$5:$F$300*(((Vinduer!$G$5:$G$300="")+(Vinduer!$G$5:$G$300=$B$2))>0)*((Vinduer!$C$5:$C$300<=Vinduer!$D$5:$D$300)*(BE$4>=Vinduer!$C$5:$C$300)*(BE$4<=Vinduer!$D$5:$D$300)+(Vinduer!$C$5:$C$300>Vinduer!$D$5:$D$300)*(((BE$4>=Vinduer!$C$5:$C$300)+(BE$4<=Vinduer!$D$5:$D$300))>0)))))))
A11: =IF(Destinasjoner!A7="","",Destinasjoner!A7) | B11: =IF(A11="","",Destinasjoner!E7) | C11: =IF(A11="","",Destinasjoner!B7) | D11: =IFERROR(SUMIFS(F11:BE11,$F$7:$BE$7,"x")/COUNTIFS($F$7:$BE$7,"x",F11:BE11,">0"),"") | E11: =IF(D11="","",_xlfn.MINIFS(F11:BE11,$F$7:$BE$7,"x",F11:BE11,">0")) | F11: =IF($A11="","",IF(COUNTIFS(Måned!$A$5:$A$2000,$A11,Måned!$C$5:$C$2000,MONTH(F$5+3))=0,"",MAX(1,MIN(5,SUMIFS(Måned!$H$5:$H$2000,Måned!$A$5:$A$2000,$A11,Måned!$C$5:$C$2000,MONTH(F$5+3))+SUMPRODUCT((Vinduer!$A$5:$A$300=$A11)*Vinduer!$F$5:$F$300*(((Vinduer!$G$5:$G$300="")+(Vinduer!$G$5:$G$300=$B$2))>0)*((Vinduer!$C$5:$C$300<=Vinduer!$D$5:$D$300)*(F$4>=Vinduer!$C$5:$C$300)*(F$4<=Vinduer!$D$5:$D$300)+(Vinduer!$C$5:$C$300>Vinduer!$D$5:$D$300)*(((F$4>=Vinduer!$C$5:$C$300)+(F$4<=Vinduer!$D$5:$D$300))>0))))))) | G11: =IF($A11="","",IF(COUNTIFS(Måned!$A$5:$A$2000,$A11,Måned!$C$5:$C$2000,MONTH(G$5+3))=0,"",MAX(1,MIN(5,SUMIFS(Måned!$H$5:$H$2000,Måned!$A$5:$A$2000,$A11,Måned!$C$5:$C$2000,MONTH(G$5+3))+SUMPRODUCT((Vinduer!$A$5:$A$300=$A11)*Vinduer!$F$5:$F$300*(((Vinduer!$G$5:$G$300="")+(Vinduer!$G$5:$G$300=$B$2))>0)*((Vinduer!$C$5:$C$300<=Vinduer!$D$5:$D$300)*(G$4>=Vinduer!$C$5:$C$300)*(G$4<=Vinduer!$D$5:$D$300)+(Vinduer!$C$5:$C$300>Vinduer!$D$5:$D$300)*(((G$4>=Vinduer!$C$5:$C$300)+(G$4<=Vinduer!$D$5:$D$300))>0))))))) | H11: =IF($A11="","",IF(COUNTIFS(Måned!$A$5:$A$2000,$A11,Måned!$C$5:$C$2000,MONTH(H$5+3))=0,"",MAX(1,MIN(5,SUMIFS(Måned!$H$5:$H$2000,Måned!$A$5:$A$2000,$A11,Måned!$C$5:$C$2000,MONTH(H$5+3))+SUMPRODUCT((Vinduer!$A$5:$A$300=$A11)*Vinduer!$F$5:$F$300*(((Vinduer!$G$5:$G$300="")+(Vinduer!$G$5:$G$300=$B$2))>0)*((Vinduer!$C$5:$C$300<=Vinduer!$D$5:$D$300)*(H$4>=Vinduer!$C$5:$C$300)*(H$4<=Vinduer!$D$5:$D$300)+(Vinduer!$C$5:$C$300>Vinduer!$D$5:$D$300)*(((H$4>=Vinduer!$C$5:$C$300)+(H$4<=Vinduer!$D$5:$D$300))>0))))))) | I11: =IF($A11="","",IF(COUNTIFS(Måned!$A$5:$A$2000,$A11,Måned!$C$5:$C$2000,MONTH(I$5+3))=0,"",MAX(1,MIN(5,SUMIFS(Måned!$H$5:$H$2000,Måned!$A$5:$A$2000,$A11,Måned!$C$5:$C$2000,MONTH(I$5+3))+SUMPRODUCT((Vinduer!$A$5:$A$300=$A11)*Vinduer!$F$5:$F$300*(((Vinduer!$G$5:$G$300="")+(Vinduer!$G$5:$G$300=$B$2))>0)*((Vinduer!$C$5:$C$300<=Vinduer!$D$5:$D$300)*(I$4>=Vinduer!$C$5:$C$300)*(I$4<=Vinduer!$D$5:$D$300)+(Vinduer!$C$5:$C$300>Vinduer!$D$5:$D$300)*(((I$4>=Vinduer!$C$5:$C$300)+(I$4<=Vinduer!$D$5:$D$300))>0))))))) | J11: =IF($A11="","",IF(COUNTIFS(Måned!$A$5:$A$2000,$A11,Måned!$C$5:$C$2000,MONTH(J$5+3))=0,"",MAX(1,MIN(5,SUMIFS(Måned!$H$5:$H$2000,Måned!$A$5:$A$2000,$A11,Måned!$C$5:$C$2000,MONTH(J$5+3))+SUMPRODUCT((Vinduer!$A$5:$A$300=$A11)*Vinduer!$F$5:$F$300*(((Vinduer!$G$5:$G$300="")+(Vinduer!$G$5:$G$300=$B$2))>0)*((Vinduer!$C$5:$C$300<=Vinduer!$D$5:$D$300)*(J$4>=Vinduer!$C$5:$C$300)*(J$4<=Vinduer!$D$5:$D$300)+(Vinduer!$C$5:$C$300>Vinduer!$D$5:$D$300)*(((J$4>=Vinduer!$C$5:$C$300)+(J$4<=Vinduer!$D$5:$D$300))>0))))))) | K11: =IF($A11="","",IF(COUNTIFS(Måned!$A$5:$A$2000,$A11,Måned!$C$5:$C$2000,MONTH(K$5+3))=0,"",MAX(1,MIN(5,SUMIFS(Måned!$H$5:$H$2000,Måned!$A$5:$A$2000,$A11,Måned!$C$5:$C$2000,MONTH(K$5+3))+SUMPRODUCT((Vinduer!$A$5:$A$300=$A11)*Vinduer!$F$5:$F$300*(((Vinduer!$G$5:$G$300="")+(Vinduer!$G$5:$G$300=$B$2))>0)*((Vinduer!$C$5:$C$300<=Vinduer!$D$5:$D$300)*(K$4>=Vinduer!$C$5:$C$300)*(K$4<=Vinduer!$D$5:$D$300)+(Vinduer!$C$5:$C$300>Vinduer!$D$5:$D$300)*(((K$4>=Vinduer!$C$5:$C$300)+(K$4<=Vinduer!$D$5:$D$300))>0))))))) | L11: =IF($A11="","",IF(COUNTIFS(Måned!$A$5:$A$2000,$A11,Måned!$C$5:$C$2000,MONTH(L$5+3))=0,"",MAX(1,MIN(5,SUMIFS(Måned!$H$5:$H$2000,Måned!$A$5:$A$2000,$A11,Måned!$C$5:$C$2000,MONTH(L$5+3))+SUMPRODUCT((Vinduer!$A$5:$A$300=$A11)*Vinduer!$F$5:$F$300*(((Vinduer!$G$5:$G$300="")+(Vinduer!$G$5:$G$300=$B$2))>0)*((Vinduer!$C$5:$C$300<=Vinduer!$D$5:$D$300)*(L$4>=Vinduer!$C$5:$C$300)*(L$4<=Vinduer!$D$5:$D$300)+(Vinduer!$C$5:$C$300>Vinduer!$D$5:$D$300)*(((L$4>=Vinduer!$C$5:$C$300)+(L$4<=Vinduer!$D$5:$D$300))>0))))))) | M11: =IF($A11="","",IF(COUNTIFS(Måned!$A$5:$A$2000,$A11,Måned!$C$5:$C$2000,MONTH(M$5+3))=0,"",MAX(1,MIN(5,SUMIFS(Måned!$H$5:$H$2000,Måned!$A$5:$A$2000,$A11,Måned!$C$5:$C$2000,MONTH(M$5+3))+SUMPRODUCT((Vinduer!$A$5:$A$300=$A11)*Vinduer!$F$5:$F$300*(((Vinduer!$G$5:$G$300="")+(Vinduer!$G$5:$G$300=$B$2))>0)*((Vinduer!$C$5:$C$300<=Vinduer!$D$5:$D$300)*(M$4>=Vinduer!$C$5:$C$300)*(M$4<=Vinduer!$D$5:$D$300)+(Vinduer!$C$5:$C$300>Vinduer!$D$5:$D$300)*(((M$4>=Vinduer!$C$5:$C$300)+(M$4<=Vinduer!$D$5:$D$300))>0))))))) | ... BE11: =IF($A11="","",IF(COUNTIFS(Måned!$A$5:$A$2000,$A11,Måned!$C$5:$C$2000,MONTH(BE$5+3))=0,"",MAX(1,MIN(5,SUMIFS(Måned!$H$5:$H$2000,Måned!$A$5:$A$2000,$A11,Måned!$C$5:$C$2000,MONTH(BE$5+3))+SUMPRODUCT((Vinduer!$A$5:$A$300=$A11)*Vinduer!$F$5:$F$300*(((Vinduer!$G$5:$G$300="")+(Vinduer!$G$5:$G$300=$B$2))>0)*((Vinduer!$C$5:$C$300<=Vinduer!$D$5:$D$300)*(BE$4>=Vinduer!$C$5:$C$300)*(BE$4<=Vinduer!$D$5:$D$300)+(Vinduer!$C$5:$C$300>Vinduer!$D$5:$D$300)*(((BE$4>=Vinduer!$C$5:$C$300)+(BE$4<=Vinduer!$D$5:$D$300))>0)))))))
A12: =IF(Destinasjoner!A8="","",Destinasjoner!A8) | B12: =IF(A12="","",Destinasjoner!E8) | C12: =IF(A12="","",Destinasjoner!B8) | D12: =IFERROR(SUMIFS(F12:BE12,$F$7:$BE$7,"x")/COUNTIFS($F$7:$BE$7,"x",F12:BE12,">0"),"") | E12: =IF(D12="","",_xlfn.MINIFS(F12:BE12,$F$7:$BE$7,"x",F12:BE12,">0")) | F12: =IF($A12="","",IF(COUNTIFS(Måned!$A$5:$A$2000,$A12,Måned!$C$5:$C$2000,MONTH(F$5+3))=0,"",MAX(1,MIN(5,SUMIFS(Måned!$H$5:$H$2000,Måned!$A$5:$A$2000,$A12,Måned!$C$5:$C$2000,MONTH(F$5+3))+SUMPRODUCT((Vinduer!$A$5:$A$300=$A12)*Vinduer!$F$5:$F$300*(((Vinduer!$G$5:$G$300="")+(Vinduer!$G$5:$G$300=$B$2))>0)*((Vinduer!$C$5:$C$300<=Vinduer!$D$5:$D$300)*(F$4>=Vinduer!$C$5:$C$300)*(F$4<=Vinduer!$D$5:$D$300)+(Vinduer!$C$5:$C$300>Vinduer!$D$5:$D$300)*(((F$4>=Vinduer!$C$5:$C$300)+(F$4<=Vinduer!$D$5:$D$300))>0))))))) | G12: =IF($A12="","",IF(COUNTIFS(Måned!$A$5:$A$2000,$A12,Måned!$C$5:$C$2000,MONTH(G$5+3))=0,"",MAX(1,MIN(5,SUMIFS(Måned!$H$5:$H$2000,Måned!$A$5:$A$2000,$A12,Måned!$C$5:$C$2000,MONTH(G$5+3))+SUMPRODUCT((Vinduer!$A$5:$A$300=$A12)*Vinduer!$F$5:$F$300*(((Vinduer!$G$5:$G$300="")+(Vinduer!$G$5:$G$300=$B$2))>0)*((Vinduer!$C$5:$C$300<=Vinduer!$D$5:$D$300)*(G$4>=Vinduer!$C$5:$C$300)*(G$4<=Vinduer!$D$5:$D$300)+(Vinduer!$C$5:$C$300>Vinduer!$D$5:$D$300)*(((G$4>=Vinduer!$C$5:$C$300)+(G$4<=Vinduer!$D$5:$D$300))>0))))))) | H12: =IF($A12="","",IF(COUNTIFS(Måned!$A$5:$A$2000,$A12,Måned!$C$5:$C$2000,MONTH(H$5+3))=0,"",MAX(1,MIN(5,SUMIFS(Måned!$H$5:$H$2000,Måned!$A$5:$A$2000,$A12,Måned!$C$5:$C$2000,MONTH(H$5+3))+SUMPRODUCT((Vinduer!$A$5:$A$300=$A12)*Vinduer!$F$5:$F$300*(((Vinduer!$G$5:$G$300="")+(Vinduer!$G$5:$G$300=$B$2))>0)*((Vinduer!$C$5:$C$300<=Vinduer!$D$5:$D$300)*(H$4>=Vinduer!$C$5:$C$300)*(H$4<=Vinduer!$D$5:$D$300)+(Vinduer!$C$5:$C$300>Vinduer!$D$5:$D$300)*(((H$4>=Vinduer!$C$5:$C$300)+(H$4<=Vinduer!$D$5:$D$300))>0))))))) | I12: =IF($A12="","",IF(COUNTIFS(Måned!$A$5:$A$2000,$A12,Måned!$C$5:$C$2000,MONTH(I$5+3))=0,"",MAX(1,MIN(5,SUMIFS(Måned!$H$5:$H$2000,Måned!$A$5:$A$2000,$A12,Måned!$C$5:$C$2000,MONTH(I$5+3))+SUMPRODUCT((Vinduer!$A$5:$A$300=$A12)*Vinduer!$F$5:$F$300*(((Vinduer!$G$5:$G$300="")+(Vinduer!$G$5:$G$300=$B$2))>0)*((Vinduer!$C$5:$C$300<=Vinduer!$D$5:$D$300)*(I$4>=Vinduer!$C$5:$C$300)*(I$4<=Vinduer!$D$5:$D$300)+(Vinduer!$C$5:$C$300>Vinduer!$D$5:$D$300)*(((I$4>=Vinduer!$C$5:$C$300)+(I$4<=Vinduer!$D$5:$D$300))>0))))))) | J12: =IF($A12="","",IF(COUNTIFS(Måned!$A$5:$A$2000,$A12,Måned!$C$5:$C$2000,MONTH(J$5+3))=0,"",MAX(1,MIN(5,SUMIFS(Måned!$H$5:$H$2000,Måned!$A$5:$A$2000,$A12,Måned!$C$5:$C$2000,MONTH(J$5+3))+SUMPRODUCT((Vinduer!$A$5:$A$300=$A12)*Vinduer!$F$5:$F$300*(((Vinduer!$G$5:$G$300="")+(Vinduer!$G$5:$G$300=$B$2))>0)*((Vinduer!$C$5:$C$300<=Vinduer!$D$5:$D$300)*(J$4>=Vinduer!$C$5:$C$300)*(J$4<=Vinduer!$D$5:$D$300)+(Vinduer!$C$5:$C$300>Vinduer!$D$5:$D$300)*(((J$4>=Vinduer!$C$5:$C$300)+(J$4<=Vinduer!$D$5:$D$300))>0))))))) | K12: =IF($A12="","",IF(COUNTIFS(Måned!$A$5:$A$2000,$A12,Måned!$C$5:$C$2000,MONTH(K$5+3))=0,"",MAX(1,MIN(5,SUMIFS(Måned!$H$5:$H$2000,Måned!$A$5:$A$2000,$A12,Måned!$C$5:$C$2000,MONTH(K$5+3))+SUMPRODUCT((Vinduer!$A$5:$A$300=$A12)*Vinduer!$F$5:$F$300*(((Vinduer!$G$5:$G$300="")+(Vinduer!$G$5:$G$300=$B$2))>0)*((Vinduer!$C$5:$C$300<=Vinduer!$D$5:$D$300)*(K$4>=Vinduer!$C$5:$C$300)*(K$4<=Vinduer!$D$5:$D$300)+(Vinduer!$C$5:$C$300>Vinduer!$D$5:$D$300)*(((K$4>=Vinduer!$C$5:$C$300)+(K$4<=Vinduer!$D$5:$D$300))>0))))))) | L12: =IF($A12="","",IF(COUNTIFS(Måned!$A$5:$A$2000,$A12,Måned!$C$5:$C$2000,MONTH(L$5+3))=0,"",MAX(1,MIN(5,SUMIFS(Måned!$H$5:$H$2000,Måned!$A$5:$A$2000,$A12,Måned!$C$5:$C$2000,MONTH(L$5+3))+SUMPRODUCT((Vinduer!$A$5:$A$300=$A12)*Vinduer!$F$5:$F$300*(((Vinduer!$G$5:$G$300="")+(Vinduer!$G$5:$G$300=$B$2))>0)*((Vinduer!$C$5:$C$300<=Vinduer!$D$5:$D$300)*(L$4>=Vinduer!$C$5:$C$300)*(L$4<=Vinduer!$D$5:$D$300)+(Vinduer!$C$5:$C$300>Vinduer!$D$5:$D$300)*(((L$4>=Vinduer!$C$5:$C$300)+(L$4<=Vinduer!$D$5:$D$300))>0))))))) | M12: =IF($A12="","",IF(COUNTIFS(Måned!$A$5:$A$2000,$A12,Måned!$C$5:$C$2000,MONTH(M$5+3))=0,"",MAX(1,MIN(5,SUMIFS(Måned!$H$5:$H$2000,Måned!$A$5:$A$2000,$A12,Måned!$C$5:$C$2000,MONTH(M$5+3))+SUMPRODUCT((Vinduer!$A$5:$A$300=$A12)*Vinduer!$F$5:$F$300*(((Vinduer!$G$5:$G$300="")+(Vinduer!$G$5:$G$300=$B$2))>0)*((Vinduer!$C$5:$C$300<=Vinduer!$D$5:$D$300)*(M$4>=Vinduer!$C$5:$C$300)*(M$4<=Vinduer!$D$5:$D$300)+(Vinduer!$C$5:$C$300>Vinduer!$D$5:$D$300)*(((M$4>=Vinduer!$C$5:$C$300)+(M$4<=Vinduer!$D$5:$D$300))>0))))))) | ... BE12: =IF($A12="","",IF(COUNTIFS(Måned!$A$5:$A$2000,$A12,Måned!$C$5:$C$2000,MONTH(BE$5+3))=0,"",MAX(1,MIN(5,SUMIFS(Måned!$H$5:$H$2000,Måned!$A$5:$A$2000,$A12,Måned!$C$5:$C$2000,MONTH(BE$5+3))+SUMPRODUCT((Vinduer!$A$5:$A$300=$A12)*Vinduer!$F$5:$F$300*(((Vinduer!$G$5:$G$300="")+(Vinduer!$G$5:$G$300=$B$2))>0)*((Vinduer!$C$5:$C$300<=Vinduer!$D$5:$D$300)*(BE$4>=Vinduer!$C$5:$C$300)*(BE$4<=Vinduer!$D$5:$D$300)+(Vinduer!$C$5:$C$300>Vinduer!$D$5:$D$300)*(((BE$4>=Vinduer!$C$5:$C$300)+(BE$4<=Vinduer!$D$5:$D$300))>0)))))))
A13: =IF(Destinasjoner!A9="","",Destinasjoner!A9) | B13: =IF(A13="","",Destinasjoner!E9) | C13: =IF(A13="","",Destinasjoner!B9) | D13: =IFERROR(SUMIFS(F13:BE13,$F$7:$BE$7,"x")/COUNTIFS($F$7:$BE$7,"x",F13:BE13,">0"),"") | E13: =IF(D13="","",_xlfn.MINIFS(F13:BE13,$F$7:$BE$7,"x",F13:BE13,">0")) | F13: =IF($A13="","",IF(COUNTIFS(Måned!$A$5:$A$2000,$A13,Måned!$C$5:$C$2000,MONTH(F$5+3))=0,"",MAX(1,MIN(5,SUMIFS(Måned!$H$5:$H$2000,Måned!$A$5:$A$2000,$A13,Måned!$C$5:$C$2000,MONTH(F$5+3))+SUMPRODUCT((Vinduer!$A$5:$A$300=$A13)*Vinduer!$F$5:$F$300*(((Vinduer!$G$5:$G$300="")+(Vinduer!$G$5:$G$300=$B$2))>0)*((Vinduer!$C$5:$C$300<=Vinduer!$D$5:$D$300)*(F$4>=Vinduer!$C$5:$C$300)*(F$4<=Vinduer!$D$5:$D$300)+(Vinduer!$C$5:$C$300>Vinduer!$D$5:$D$300)*(((F$4>=Vinduer!$C$5:$C$300)+(F$4<=Vinduer!$D$5:$D$300))>0))))))) | G13: =IF($A13="","",IF(COUNTIFS(Måned!$A$5:$A$2000,$A13,Måned!$C$5:$C$2000,MONTH(G$5+3))=0,"",MAX(1,MIN(5,SUMIFS(Måned!$H$5:$H$2000,Måned!$A$5:$A$2000,$A13,Måned!$C$5:$C$2000,MONTH(G$5+3))+SUMPRODUCT((Vinduer!$A$5:$A$300=$A13)*Vinduer!$F$5:$F$300*(((Vinduer!$G$5:$G$300="")+(Vinduer!$G$5:$G$300=$B$2))>0)*((Vinduer!$C$5:$C$300<=Vinduer!$D$5:$D$300)*(G$4>=Vinduer!$C$5:$C$300)*(G$4<=Vinduer!$D$5:$D$300)+(Vinduer!$C$5:$C$300>Vinduer!$D$5:$D$300)*(((G$4>=Vinduer!$C$5:$C$300)+(G$4<=Vinduer!$D$5:$D$300))>0))))))) | H13: =IF($A13="","",IF(COUNTIFS(Måned!$A$5:$A$2000,$A13,Måned!$C$5:$C$2000,MONTH(H$5+3))=0,"",MAX(1,MIN(5,SUMIFS(Måned!$H$5:$H$2000,Måned!$A$5:$A$2000,$A13,Måned!$C$5:$C$2000,MONTH(H$5+3))+SUMPRODUCT((Vinduer!$A$5:$A$300=$A13)*Vinduer!$F$5:$F$300*(((Vinduer!$G$5:$G$300="")+(Vinduer!$G$5:$G$300=$B$2))>0)*((Vinduer!$C$5:$C$300<=Vinduer!$D$5:$D$300)*(H$4>=Vinduer!$C$5:$C$300)*(H$4<=Vinduer!$D$5:$D$300)+(Vinduer!$C$5:$C$300>Vinduer!$D$5:$D$300)*(((H$4>=Vinduer!$C$5:$C$300)+(H$4<=Vinduer!$D$5:$D$300))>0))))))) | I13: =IF($A13="","",IF(COUNTIFS(Måned!$A$5:$A$2000,$A13,Måned!$C$5:$C$2000,MONTH(I$5+3))=0,"",MAX(1,MIN(5,SUMIFS(Måned!$H$5:$H$2000,Måned!$A$5:$A$2000,$A13,Måned!$C$5:$C$2000,MONTH(I$5+3))+SUMPRODUCT((Vinduer!$A$5:$A$300=$A13)*Vinduer!$F$5:$F$300*(((Vinduer!$G$5:$G$300="")+(Vinduer!$G$5:$G$300=$B$2))>0)*((Vinduer!$C$5:$C$300<=Vinduer!$D$5:$D$300)*(I$4>=Vinduer!$C$5:$C$300)*(I$4<=Vinduer!$D$5:$D$300)+(Vinduer!$C$5:$C$300>Vinduer!$D$5:$D$300)*(((I$4>=Vinduer!$C$5:$C$300)+(I$4<=Vinduer!$D$5:$D$300))>0))))))) | J13: =IF($A13="","",IF(COUNTIFS(Måned!$A$5:$A$2000,$A13,Måned!$C$5:$C$2000,MONTH(J$5+3))=0,"",MAX(1,MIN(5,SUMIFS(Måned!$H$5:$H$2000,Måned!$A$5:$A$2000,$A13,Måned!$C$5:$C$2000,MONTH(J$5+3))+SUMPRODUCT((Vinduer!$A$5:$A$300=$A13)*Vinduer!$F$5:$F$300*(((Vinduer!$G$5:$G$300="")+(Vinduer!$G$5:$G$300=$B$2))>0)*((Vinduer!$C$5:$C$300<=Vinduer!$D$5:$D$300)*(J$4>=Vinduer!$C$5:$C$300)*(J$4<=Vinduer!$D$5:$D$300)+(Vinduer!$C$5:$C$300>Vinduer!$D$5:$D$300)*(((J$4>=Vinduer!$C$5:$C$300)+(J$4<=Vinduer!$D$5:$D$300))>0))))))) | K13: =IF($A13="","",IF(COUNTIFS(Måned!$A$5:$A$2000,$A13,Måned!$C$5:$C$2000,MONTH(K$5+3))=0,"",MAX(1,MIN(5,SUMIFS(Måned!$H$5:$H$2000,Måned!$A$5:$A$2000,$A13,Måned!$C$5:$C$2000,MONTH(K$5+3))+SUMPRODUCT((Vinduer!$A$5:$A$300=$A13)*Vinduer!$F$5:$F$300*(((Vinduer!$G$5:$G$300="")+(Vinduer!$G$5:$G$300=$B$2))>0)*((Vinduer!$C$5:$C$300<=Vinduer!$D$5:$D$300)*(K$4>=Vinduer!$C$5:$C$300)*(K$4<=Vinduer!$D$5:$D$300)+(Vinduer!$C$5:$C$300>Vinduer!$D$5:$D$300)*(((K$4>=Vinduer!$C$5:$C$300)+(K$4<=Vinduer!$D$5:$D$300))>0))))))) | L13: =IF($A13="","",IF(COUNTIFS(Måned!$A$5:$A$2000,$A13,Måned!$C$5:$C$2000,MONTH(L$5+3))=0,"",MAX(1,MIN(5,SUMIFS(Måned!$H$5:$H$2000,Måned!$A$5:$A$2000,$A13,Måned!$C$5:$C$2000,MONTH(L$5+3))+SUMPRODUCT((Vinduer!$A$5:$A$300=$A13)*Vinduer!$F$5:$F$300*(((Vinduer!$G$5:$G$300="")+(Vinduer!$G$5:$G$300=$B$2))>0)*((Vinduer!$C$5:$C$300<=Vinduer!$D$5:$D$300)*(L$4>=Vinduer!$C$5:$C$300)*(L$4<=Vinduer!$D$5:$D$300)+(Vinduer!$C$5:$C$300>Vinduer!$D$5:$D$300)*(((L$4>=Vinduer!$C$5:$C$300)+(L$4<=Vinduer!$D$5:$D$300))>0))))))) | M13: =IF($A13="","",IF(COUNTIFS(Måned!$A$5:$A$2000,$A13,Måned!$C$5:$C$2000,MONTH(M$5+3))=0,"",MAX(1,MIN(5,SUMIFS(Måned!$H$5:$H$2000,Måned!$A$5:$A$2000,$A13,Måned!$C$5:$C$2000,MONTH(M$5+3))+SUMPRODUCT((Vinduer!$A$5:$A$300=$A13)*Vinduer!$F$5:$F$300*(((Vinduer!$G$5:$G$300="")+(Vinduer!$G$5:$G$300=$B$2))>0)*((Vinduer!$C$5:$C$300<=Vinduer!$D$5:$D$300)*(M$4>=Vinduer!$C$5:$C$300)*(M$4<=Vinduer!$D$5:$D$300)+(Vinduer!$C$5:$C$300>Vinduer!$D$5:$D$300)*(((M$4>=Vinduer!$C$5:$C$300)+(M$4<=Vinduer!$D$5:$D$300))>0))))))) | ... BE13: =IF($A13="","",IF(COUNTIFS(Måned!$A$5:$A$2000,$A13,Måned!$C$5:$C$2000,MONTH(BE$5+3))=0,"",MAX(1,MIN(5,SUMIFS(Måned!$H$5:$H$2000,Måned!$A$5:$A$2000,$A13,Måned!$C$5:$C$2000,MONTH(BE$5+3))+SUMPRODUCT((Vinduer!$A$5:$A$300=$A13)*Vinduer!$F$5:$F$300*(((Vinduer!$G$5:$G$300="")+(Vinduer!$G$5:$G$300=$B$2))>0)*((Vinduer!$C$5:$C$300<=Vinduer!$D$5:$D$300)*(BE$4>=Vinduer!$C$5:$C$300)*(BE$4<=Vinduer!$D$5:$D$300)+(Vinduer!$C$5:$C$300>Vinduer!$D$5:$D$300)*(((BE$4>=Vinduer!$C$5:$C$300)+(BE$4<=Vinduer!$D$5:$D$300))>0)))))))
A14: =IF(Destinasjoner!A10="","",Destinasjoner!A10) | B14: =IF(A14="","",Destinasjoner!E10) | C14: =IF(A14="","",Destinasjoner!B10) | D14: =IFERROR(SUMIFS(F14:BE14,$F$7:$BE$7,"x")/COUNTIFS($F$7:$BE$7,"x",F14:BE14,">0"),"") | E14: =IF(D14="","",_xlfn.MINIFS(F14:BE14,$F$7:$BE$7,"x",F14:BE14,">0")) | F14: =IF($A14="","",IF(COUNTIFS(Måned!$A$5:$A$2000,$A14,Måned!$C$5:$C$2000,MONTH(F$5+3))=0,"",MAX(1,MIN(5,SUMIFS(Måned!$H$5:$H$2000,Måned!$A$5:$A$2000,$A14,Måned!$C$5:$C$2000,MONTH(F$5+3))+SUMPRODUCT((Vinduer!$A$5:$A$300=$A14)*Vinduer!$F$5:$F$300*(((Vinduer!$G$5:$G$300="")+(Vinduer!$G$5:$G$300=$B$2))>0)*((Vinduer!$C$5:$C$300<=Vinduer!$D$5:$D$300)*(F$4>=Vinduer!$C$5:$C$300)*(F$4<=Vinduer!$D$5:$D$300)+(Vinduer!$C$5:$C$300>Vinduer!$D$5:$D$300)*(((F$4>=Vinduer!$C$5:$C$300)+(F$4<=Vinduer!$D$5:$D$300))>0))))))) | G14: =IF($A14="","",IF(COUNTIFS(Måned!$A$5:$A$2000,$A14,Måned!$C$5:$C$2000,MONTH(G$5+3))=0,"",MAX(1,MIN(5,SUMIFS(Måned!$H$5:$H$2000,Måned!$A$5:$A$2000,$A14,Måned!$C$5:$C$2000,MONTH(G$5+3))+SUMPRODUCT((Vinduer!$A$5:$A$300=$A14)*Vinduer!$F$5:$F$300*(((Vinduer!$G$5:$G$300="")+(Vinduer!$G$5:$G$300=$B$2))>0)*((Vinduer!$C$5:$C$300<=Vinduer!$D$5:$D$300)*(G$4>=Vinduer!$C$5:$C$300)*(G$4<=Vinduer!$D$5:$D$300)+(Vinduer!$C$5:$C$300>Vinduer!$D$5:$D$300)*(((G$4>=Vinduer!$C$5:$C$300)+(G$4<=Vinduer!$D$5:$D$300))>0))))))) | H14: =IF($A14="","",IF(COUNTIFS(Måned!$A$5:$A$2000,$A14,Måned!$C$5:$C$2000,MONTH(H$5+3))=0,"",MAX(1,MIN(5,SUMIFS(Måned!$H$5:$H$2000,Måned!$A$5:$A$2000,$A14,Måned!$C$5:$C$2000,MONTH(H$5+3))+SUMPRODUCT((Vinduer!$A$5:$A$300=$A14)*Vinduer!$F$5:$F$300*(((Vinduer!$G$5:$G$300="")+(Vinduer!$G$5:$G$300=$B$2))>0)*((Vinduer!$C$5:$C$300<=Vinduer!$D$5:$D$300)*(H$4>=Vinduer!$C$5:$C$300)*(H$4<=Vinduer!$D$5:$D$300)+(Vinduer!$C$5:$C$300>Vinduer!$D$5:$D$300)*(((H$4>=Vinduer!$C$5:$C$300)+(H$4<=Vinduer!$D$5:$D$300))>0))))))) | I14: =IF($A14="","",IF(COUNTIFS(Måned!$A$5:$A$2000,$A14,Måned!$C$5:$C$2000,MONTH(I$5+3))=0,"",MAX(1,MIN(5,SUMIFS(Måned!$H$5:$H$2000,Måned!$A$5:$A$2000,$A14,Måned!$C$5:$C$2000,MONTH(I$5+3))+SUMPRODUCT((Vinduer!$A$5:$A$300=$A14)*Vinduer!$F$5:$F$300*(((Vinduer!$G$5:$G$300="")+(Vinduer!$G$5:$G$300=$B$2))>0)*((Vinduer!$C$5:$C$300<=Vinduer!$D$5:$D$300)*(I$4>=Vinduer!$C$5:$C$300)*(I$4<=Vinduer!$D$5:$D$300)+(Vinduer!$C$5:$C$300>Vinduer!$D$5:$D$300)*(((I$4>=Vinduer!$C$5:$C$300)+(I$4<=Vinduer!$D$5:$D$300))>0))))))) | J14: =IF($A14="","",IF(COUNTIFS(Måned!$A$5:$A$2000,$A14,Måned!$C$5:$C$2000,MONTH(J$5+3))=0,"",MAX(1,MIN(5,SUMIFS(Måned!$H$5:$H$2000,Måned!$A$5:$A$2000,$A14,Måned!$C$5:$C$2000,MONTH(J$5+3))+SUMPRODUCT((Vinduer!$A$5:$A$300=$A14)*Vinduer!$F$5:$F$300*(((Vinduer!$G$5:$G$300="")+(Vinduer!$G$5:$G$300=$B$2))>0)*((Vinduer!$C$5:$C$300<=Vinduer!$D$5:$D$300)*(J$4>=Vinduer!$C$5:$C$300)*(J$4<=Vinduer!$D$5:$D$300)+(Vinduer!$C$5:$C$300>Vinduer!$D$5:$D$300)*(((J$4>=Vinduer!$C$5:$C$300)+(J$4<=Vinduer!$D$5:$D$300))>0))))))) | K14: =IF($A14="","",IF(COUNTIFS(Måned!$A$5:$A$2000,$A14,Måned!$C$5:$C$2000,MONTH(K$5+3))=0,"",MAX(1,MIN(5,SUMIFS(Måned!$H$5:$H$2000,Måned!$A$5:$A$2000,$A14,Måned!$C$5:$C$2000,MONTH(K$5+3))+SUMPRODUCT((Vinduer!$A$5:$A$300=$A14)*Vinduer!$F$5:$F$300*(((Vinduer!$G$5:$G$300="")+(Vinduer!$G$5:$G$300=$B$2))>0)*((Vinduer!$C$5:$C$300<=Vinduer!$D$5:$D$300)*(K$4>=Vinduer!$C$5:$C$300)*(K$4<=Vinduer!$D$5:$D$300)+(Vinduer!$C$5:$C$300>Vinduer!$D$5:$D$300)*(((K$4>=Vinduer!$C$5:$C$300)+(K$4<=Vinduer!$D$5:$D$300))>0))))))) | L14: =IF($A14="","",IF(COUNTIFS(Måned!$A$5:$A$2000,$A14,Måned!$C$5:$C$2000,MONTH(L$5+3))=0,"",MAX(1,MIN(5,SUMIFS(Måned!$H$5:$H$2000,Måned!$A$5:$A$2000,$A14,Måned!$C$5:$C$2000,MONTH(L$5+3))+SUMPRODUCT((Vinduer!$A$5:$A$300=$A14)*Vinduer!$F$5:$F$300*(((Vinduer!$G$5:$G$300="")+(Vinduer!$G$5:$G$300=$B$2))>0)*((Vinduer!$C$5:$C$300<=Vinduer!$D$5:$D$300)*(L$4>=Vinduer!$C$5:$C$300)*(L$4<=Vinduer!$D$5:$D$300)+(Vinduer!$C$5:$C$300>Vinduer!$D$5:$D$300)*(((L$4>=Vinduer!$C$5:$C$300)+(L$4<=Vinduer!$D$5:$D$300))>0))))))) | M14: =IF($A14="","",IF(COUNTIFS(Måned!$A$5:$A$2000,$A14,Måned!$C$5:$C$2000,MONTH(M$5+3))=0,"",MAX(1,MIN(5,SUMIFS(Måned!$H$5:$H$2000,Måned!$A$5:$A$2000,$A14,Måned!$C$5:$C$2000,MONTH(M$5+3))+SUMPRODUCT((Vinduer!$A$5:$A$300=$A14)*Vinduer!$F$5:$F$300*(((Vinduer!$G$5:$G$300="")+(Vinduer!$G$5:$G$300=$B$2))>0)*((Vinduer!$C$5:$C$300<=Vinduer!$D$5:$D$300)*(M$4>=Vinduer!$C$5:$C$300)*(M$4<=Vinduer!$D$5:$D$300)+(Vinduer!$C$5:$C$300>Vinduer!$D$5:$D$300)*(((M$4>=Vinduer!$C$5:$C$300)+(M$4<=Vinduer!$D$5:$D$300))>0))))))) | ... BE14: =IF($A14="","",IF(COUNTIFS(Måned!$A$5:$A$2000,$A14,Måned!$C$5:$C$2000,MONTH(BE$5+3))=0,"",MAX(1,MIN(5,SUMIFS(Måned!$H$5:$H$2000,Måned!$A$5:$A$2000,$A14,Måned!$C$5:$C$2000,MONTH(BE$5+3))+SUMPRODUCT((Vinduer!$A$5:$A$300=$A14)*Vinduer!$F$5:$F$300*(((Vinduer!$G$5:$G$300="")+(Vinduer!$G$5:$G$300=$B$2))>0)*((Vinduer!$C$5:$C$300<=Vinduer!$D$5:$D$300)*(BE$4>=Vinduer!$C$5:$C$300)*(BE$4<=Vinduer!$D$5:$D$300)+(Vinduer!$C$5:$C$300>Vinduer!$D$5:$D$300)*(((BE$4>=Vinduer!$C$5:$C$300)+(BE$4<=Vinduer!$D$5:$D$300))>0)))))))
A15: =IF(Destinasjoner!A11="","",Destinasjoner!A11) | B15: =IF(A15="","",Destinasjoner!E11) | C15: =IF(A15="","",Destinasjoner!B11) | D15: =IFERROR(SUMIFS(F15:BE15,$F$7:$BE$7,"x")/COUNTIFS($F$7:$BE$7,"x",F15:BE15,">0"),"") | E15: =IF(D15="","",_xlfn.MINIFS(F15:BE15,$F$7:$BE$7,"x",F15:BE15,">0")) | F15: =IF($A15="","",IF(COUNTIFS(Måned!$A$5:$A$2000,$A15,Måned!$C$5:$C$2000,MONTH(F$5+3))=0,"",MAX(1,MIN(5,SUMIFS(Måned!$H$5:$H$2000,Måned!$A$5:$A$2000,$A15,Måned!$C$5:$C$2000,MONTH(F$5+3))+SUMPRODUCT((Vinduer!$A$5:$A$300=$A15)*Vinduer!$F$5:$F$300*(((Vinduer!$G$5:$G$300="")+(Vinduer!$G$5:$G$300=$B$2))>0)*((Vinduer!$C$5:$C$300<=Vinduer!$D$5:$D$300)*(F$4>=Vinduer!$C$5:$C$300)*(F$4<=Vinduer!$D$5:$D$300)+(Vinduer!$C$5:$C$300>Vinduer!$D$5:$D$300)*(((F$4>=Vinduer!$C$5:$C$300)+(F$4<=Vinduer!$D$5:$D$300))>0))))))) | G15: =IF($A15="","",IF(COUNTIFS(Måned!$A$5:$A$2000,$A15,Måned!$C$5:$C$2000,MONTH(G$5+3))=0,"",MAX(1,MIN(5,SUMIFS(Måned!$H$5:$H$2000,Måned!$A$5:$A$2000,$A15,Måned!$C$5:$C$2000,MONTH(G$5+3))+SUMPRODUCT((Vinduer!$A$5:$A$300=$A15)*Vinduer!$F$5:$F$300*(((Vinduer!$G$5:$G$300="")+(Vinduer!$G$5:$G$300=$B$2))>0)*((Vinduer!$C$5:$C$300<=Vinduer!$D$5:$D$300)*(G$4>=Vinduer!$C$5:$C$300)*(G$4<=Vinduer!$D$5:$D$300)+(Vinduer!$C$5:$C$300>Vinduer!$D$5:$D$300)*(((G$4>=Vinduer!$C$5:$C$300)+(G$4<=Vinduer!$D$5:$D$300))>0))))))) | H15: =IF($A15="","",IF(COUNTIFS(Måned!$A$5:$A$2000,$A15,Måned!$C$5:$C$2000,MONTH(H$5+3))=0,"",MAX(1,MIN(5,SUMIFS(Måned!$H$5:$H$2000,Måned!$A$5:$A$2000,$A15,Måned!$C$5:$C$2000,MONTH(H$5+3))+SUMPRODUCT((Vinduer!$A$5:$A$300=$A15)*Vinduer!$F$5:$F$300*(((Vinduer!$G$5:$G$300="")+(Vinduer!$G$5:$G$300=$B$2))>0)*((Vinduer!$C$5:$C$300<=Vinduer!$D$5:$D$300)*(H$4>=Vinduer!$C$5:$C$300)*(H$4<=Vinduer!$D$5:$D$300)+(Vinduer!$C$5:$C$300>Vinduer!$D$5:$D$300)*(((H$4>=Vinduer!$C$5:$C$300)+(H$4<=Vinduer!$D$5:$D$300))>0))))))) | I15: =IF($A15="","",IF(COUNTIFS(Måned!$A$5:$A$2000,$A15,Måned!$C$5:$C$2000,MONTH(I$5+3))=0,"",MAX(1,MIN(5,SUMIFS(Måned!$H$5:$H$2000,Måned!$A$5:$A$2000,$A15,Måned!$C$5:$C$2000,MONTH(I$5+3))+SUMPRODUCT((Vinduer!$A$5:$A$300=$A15)*Vinduer!$F$5:$F$300*(((Vinduer!$G$5:$G$300="")+(Vinduer!$G$5:$G$300=$B$2))>0)*((Vinduer!$C$5:$C$300<=Vinduer!$D$5:$D$300)*(I$4>=Vinduer!$C$5:$C$300)*(I$4<=Vinduer!$D$5:$D$300)+(Vinduer!$C$5:$C$300>Vinduer!$D$5:$D$300)*(((I$4>=Vinduer!$C$5:$C$300)+(I$4<=Vinduer!$D$5:$D$300))>0))))))) | J15: =IF($A15="","",IF(COUNTIFS(Måned!$A$5:$A$2000,$A15,Måned!$C$5:$C$2000,MONTH(J$5+3))=0,"",MAX(1,MIN(5,SUMIFS(Måned!$H$5:$H$2000,Måned!$A$5:$A$2000,$A15,Måned!$C$5:$C$2000,MONTH(J$5+3))+SUMPRODUCT((Vinduer!$A$5:$A$300=$A15)*Vinduer!$F$5:$F$300*(((Vinduer!$G$5:$G$300="")+(Vinduer!$G$5:$G$300=$B$2))>0)*((Vinduer!$C$5:$C$300<=Vinduer!$D$5:$D$300)*(J$4>=Vinduer!$C$5:$C$300)*(J$4<=Vinduer!$D$5:$D$300)+(Vinduer!$C$5:$C$300>Vinduer!$D$5:$D$300)*(((J$4>=Vinduer!$C$5:$C$300)+(J$4<=Vinduer!$D$5:$D$300))>0))))))) | K15: =IF($A15="","",IF(COUNTIFS(Måned!$A$5:$A$2000,$A15,Måned!$C$5:$C$2000,MONTH(K$5+3))=0,"",MAX(1,MIN(5,SUMIFS(Måned!$H$5:$H$2000,Måned!$A$5:$A$2000,$A15,Måned!$C$5:$C$2000,MONTH(K$5+3))+SUMPRODUCT((Vinduer!$A$5:$A$300=$A15)*Vinduer!$F$5:$F$300*(((Vinduer!$G$5:$G$300="")+(Vinduer!$G$5:$G$300=$B$2))>0)*((Vinduer!$C$5:$C$300<=Vinduer!$D$5:$D$300)*(K$4>=Vinduer!$C$5:$C$300)*(K$4<=Vinduer!$D$5:$D$300)+(Vinduer!$C$5:$C$300>Vinduer!$D$5:$D$300)*(((K$4>=Vinduer!$C$5:$C$300)+(K$4<=Vinduer!$D$5:$D$300))>0))))))) | L15: =IF($A15="","",IF(COUNTIFS(Måned!$A$5:$A$2000,$A15,Måned!$C$5:$C$2000,MONTH(L$5+3))=0,"",MAX(1,MIN(5,SUMIFS(Måned!$H$5:$H$2000,Måned!$A$5:$A$2000,$A15,Måned!$C$5:$C$2000,MONTH(L$5+3))+SUMPRODUCT((Vinduer!$A$5:$A$300=$A15)*Vinduer!$F$5:$F$300*(((Vinduer!$G$5:$G$300="")+(Vinduer!$G$5:$G$300=$B$2))>0)*((Vinduer!$C$5:$C$300<=Vinduer!$D$5:$D$300)*(L$4>=Vinduer!$C$5:$C$300)*(L$4<=Vinduer!$D$5:$D$300)+(Vinduer!$C$5:$C$300>Vinduer!$D$5:$D$300)*(((L$4>=Vinduer!$C$5:$C$300)+(L$4<=Vinduer!$D$5:$D$300))>0))))))) | M15: =IF($A15="","",IF(COUNTIFS(Måned!$A$5:$A$2000,$A15,Måned!$C$5:$C$2000,MONTH(M$5+3))=0,"",MAX(1,MIN(5,SUMIFS(Måned!$H$5:$H$2000,Måned!$A$5:$A$2000,$A15,Måned!$C$5:$C$2000,MONTH(M$5+3))+SUMPRODUCT((Vinduer!$A$5:$A$300=$A15)*Vinduer!$F$5:$F$300*(((Vinduer!$G$5:$G$300="")+(Vinduer!$G$5:$G$300=$B$2))>0)*((Vinduer!$C$5:$C$300<=Vinduer!$D$5:$D$300)*(M$4>=Vinduer!$C$5:$C$300)*(M$4<=Vinduer!$D$5:$D$300)+(Vinduer!$C$5:$C$300>Vinduer!$D$5:$D$300)*(((M$4>=Vinduer!$C$5:$C$300)+(M$4<=Vinduer!$D$5:$D$300))>0))))))) | ... BE15: =IF($A15="","",IF(COUNTIFS(Måned!$A$5:$A$2000,$A15,Måned!$C$5:$C$2000,MONTH(BE$5+3))=0,"",MAX(1,MIN(5,SUMIFS(Måned!$H$5:$H$2000,Måned!$A$5:$A$2000,$A15,Måned!$C$5:$C$2000,MONTH(BE$5+3))+SUMPRODUCT((Vinduer!$A$5:$A$300=$A15)*Vinduer!$F$5:$F$300*(((Vinduer!$G$5:$G$300="")+(Vinduer!$G$5:$G$300=$B$2))>0)*((Vinduer!$C$5:$C$300<=Vinduer!$D$5:$D$300)*(BE$4>=Vinduer!$C$5:$C$300)*(BE$4<=Vinduer!$D$5:$D$300)+(Vinduer!$C$5:$C$300>Vinduer!$D$5:$D$300)*(((BE$4>=Vinduer!$C$5:$C$300)+(BE$4<=Vinduer!$D$5:$D$300))>0)))))))
A16: =IF(Destinasjoner!A12="","",Destinasjoner!A12) | B16: =IF(A16="","",Destinasjoner!E12) | C16: =IF(A16="","",Destinasjoner!B12) | D16: =IFERROR(SUMIFS(F16:BE16,$F$7:$BE$7,"x")/COUNTIFS($F$7:$BE$7,"x",F16:BE16,">0"),"") | E16: =IF(D16="","",_xlfn.MINIFS(F16:BE16,$F$7:$BE$7,"x",F16:BE16,">0")) | F16: =IF($A16="","",IF(COUNTIFS(Måned!$A$5:$A$2000,$A16,Måned!$C$5:$C$2000,MONTH(F$5+3))=0,"",MAX(1,MIN(5,SUMIFS(Måned!$H$5:$H$2000,Måned!$A$5:$A$2000,$A16,Måned!$C$5:$C$2000,MONTH(F$5+3))+SUMPRODUCT((Vinduer!$A$5:$A$300=$A16)*Vinduer!$F$5:$F$300*(((Vinduer!$G$5:$G$300="")+(Vinduer!$G$5:$G$300=$B$2))>0)*((Vinduer!$C$5:$C$300<=Vinduer!$D$5:$D$300)*(F$4>=Vinduer!$C$5:$C$300)*(F$4<=Vinduer!$D$5:$D$300)+(Vinduer!$C$5:$C$300>Vinduer!$D$5:$D$300)*(((F$4>=Vinduer!$C$5:$C$300)+(F$4<=Vinduer!$D$5:$D$300))>0))))))) | G16: =IF($A16="","",IF(COUNTIFS(Måned!$A$5:$A$2000,$A16,Måned!$C$5:$C$2000,MONTH(G$5+3))=0,"",MAX(1,MIN(5,SUMIFS(Måned!$H$5:$H$2000,Måned!$A$5:$A$2000,$A16,Måned!$C$5:$C$2000,MONTH(G$5+3))+SUMPRODUCT((Vinduer!$A$5:$A$300=$A16)*Vinduer!$F$5:$F$300*(((Vinduer!$G$5:$G$300="")+(Vinduer!$G$5:$G$300=$B$2))>0)*((Vinduer!$C$5:$C$300<=Vinduer!$D$5:$D$300)*(G$4>=Vinduer!$C$5:$C$300)*(G$4<=Vinduer!$D$5:$D$300)+(Vinduer!$C$5:$C$300>Vinduer!$D$5:$D$300)*(((G$4>=Vinduer!$C$5:$C$300)+(G$4<=Vinduer!$D$5:$D$300))>0))))))) | H16: =IF($A16="","",IF(COUNTIFS(Måned!$A$5:$A$2000,$A16,Måned!$C$5:$C$2000,MONTH(H$5+3))=0,"",MAX(1,MIN(5,SUMIFS(Måned!$H$5:$H$2000,Måned!$A$5:$A$2000,$A16,Måned!$C$5:$C$2000,MONTH(H$5+3))+SUMPRODUCT((Vinduer!$A$5:$A$300=$A16)*Vinduer!$F$5:$F$300*(((Vinduer!$G$5:$G$300="")+(Vinduer!$G$5:$G$300=$B$2))>0)*((Vinduer!$C$5:$C$300<=Vinduer!$D$5:$D$300)*(H$4>=Vinduer!$C$5:$C$300)*(H$4<=Vinduer!$D$5:$D$300)+(Vinduer!$C$5:$C$300>Vinduer!$D$5:$D$300)*(((H$4>=Vinduer!$C$5:$C$300)+(H$4<=Vinduer!$D$5:$D$300))>0))))))) | I16: =IF($A16="","",IF(COUNTIFS(Måned!$A$5:$A$2000,$A16,Måned!$C$5:$C$2000,MONTH(I$5+3))=0,"",MAX(1,MIN(5,SUMIFS(Måned!$H$5:$H$2000,Måned!$A$5:$A$2000,$A16,Måned!$C$5:$C$2000,MONTH(I$5+3))+SUMPRODUCT((Vinduer!$A$5:$A$300=$A16)*Vinduer!$F$5:$F$300*(((Vinduer!$G$5:$G$300="")+(Vinduer!$G$5:$G$300=$B$2))>0)*((Vinduer!$C$5:$C$300<=Vinduer!$D$5:$D$300)*(I$4>=Vinduer!$C$5:$C$300)*(I$4<=Vinduer!$D$5:$D$300)+(Vinduer!$C$5:$C$300>Vinduer!$D$5:$D$300)*(((I$4>=Vinduer!$C$5:$C$300)+(I$4<=Vinduer!$D$5:$D$300))>0))))))) | J16: =IF($A16="","",IF(COUNTIFS(Måned!$A$5:$A$2000,$A16,Måned!$C$5:$C$2000,MONTH(J$5+3))=0,"",MAX(1,MIN(5,SUMIFS(Måned!$H$5:$H$2000,Måned!$A$5:$A$2000,$A16,Måned!$C$5:$C$2000,MONTH(J$5+3))+SUMPRODUCT((Vinduer!$A$5:$A$300=$A16)*Vinduer!$F$5:$F$300*(((Vinduer!$G$5:$G$300="")+(Vinduer!$G$5:$G$300=$B$2))>0)*((Vinduer!$C$5:$C$300<=Vinduer!$D$5:$D$300)*(J$4>=Vinduer!$C$5:$C$300)*(J$4<=Vinduer!$D$5:$D$300)+(Vinduer!$C$5:$C$300>Vinduer!$D$5:$D$300)*(((J$4>=Vinduer!$C$5:$C$300)+(J$4<=Vinduer!$D$5:$D$300))>0))))))) | K16: =IF($A16="","",IF(COUNTIFS(Måned!$A$5:$A$2000,$A16,Måned!$C$5:$C$2000,MONTH(K$5+3))=0,"",MAX(1,MIN(5,SUMIFS(Måned!$H$5:$H$2000,Måned!$A$5:$A$2000,$A16,Måned!$C$5:$C$2000,MONTH(K$5+3))+SUMPRODUCT((Vinduer!$A$5:$A$300=$A16)*Vinduer!$F$5:$F$300*(((Vinduer!$G$5:$G$300="")+(Vinduer!$G$5:$G$300=$B$2))>0)*((Vinduer!$C$5:$C$300<=Vinduer!$D$5:$D$300)*(K$4>=Vinduer!$C$5:$C$300)*(K$4<=Vinduer!$D$5:$D$300)+(Vinduer!$C$5:$C$300>Vinduer!$D$5:$D$300)*(((K$4>=Vinduer!$C$5:$C$300)+(K$4<=Vinduer!$D$5:$D$300))>0))))))) | L16: =IF($A16="","",IF(COUNTIFS(Måned!$A$5:$A$2000,$A16,Måned!$C$5:$C$2000,MONTH(L$5+3))=0,"",MAX(1,MIN(5,SUMIFS(Måned!$H$5:$H$2000,Måned!$A$5:$A$2000,$A16,Måned!$C$5:$C$2000,MONTH(L$5+3))+SUMPRODUCT((Vinduer!$A$5:$A$300=$A16)*Vinduer!$F$5:$F$300*(((Vinduer!$G$5:$G$300="")+(Vinduer!$G$5:$G$300=$B$2))>0)*((Vinduer!$C$5:$C$300<=Vinduer!$D$5:$D$300)*(L$4>=Vinduer!$C$5:$C$300)*(L$4<=Vinduer!$D$5:$D$300)+(Vinduer!$C$5:$C$300>Vinduer!$D$5:$D$300)*(((L$4>=Vinduer!$C$5:$C$300)+(L$4<=Vinduer!$D$5:$D$300))>0))))))) | M16: =IF($A16="","",IF(COUNTIFS(Måned!$A$5:$A$2000,$A16,Måned!$C$5:$C$2000,MONTH(M$5+3))=0,"",MAX(1,MIN(5,SUMIFS(Måned!$H$5:$H$2000,Måned!$A$5:$A$2000,$A16,Måned!$C$5:$C$2000,MONTH(M$5+3))+SUMPRODUCT((Vinduer!$A$5:$A$300=$A16)*Vinduer!$F$5:$F$300*(((Vinduer!$G$5:$G$300="")+(Vinduer!$G$5:$G$300=$B$2))>0)*((Vinduer!$C$5:$C$300<=Vinduer!$D$5:$D$300)*(M$4>=Vinduer!$C$5:$C$300)*(M$4<=Vinduer!$D$5:$D$300)+(Vinduer!$C$5:$C$300>Vinduer!$D$5:$D$300)*(((M$4>=Vinduer!$C$5:$C$300)+(M$4<=Vinduer!$D$5:$D$300))>0))))))) | ... BE16: =IF($A16="","",IF(COUNTIFS(Måned!$A$5:$A$2000,$A16,Måned!$C$5:$C$2000,MONTH(BE$5+3))=0,"",MAX(1,MIN(5,SUMIFS(Måned!$H$5:$H$2000,Måned!$A$5:$A$2000,$A16,Måned!$C$5:$C$2000,MONTH(BE$5+3))+SUMPRODUCT((Vinduer!$A$5:$A$300=$A16)*Vinduer!$F$5:$F$300*(((Vinduer!$G$5:$G$300="")+(Vinduer!$G$5:$G$300=$B$2))>0)*((Vinduer!$C$5:$C$300<=Vinduer!$D$5:$D$300)*(BE$4>=Vinduer!$C$5:$C$300)*(BE$4<=Vinduer!$D$5:$D$300)+(Vinduer!$C$5:$C$300>Vinduer!$D$5:$D$300)*(((BE$4>=Vinduer!$C$5:$C$300)+(BE$4<=Vinduer!$D$5:$D$300))>0)))))))
A17: =IF(Destinasjoner!A13="","",Destinasjoner!A13) | B17: =IF(A17="","",Destinasjoner!E13) | C17: =IF(A17="","",Destinasjoner!B13) | D17: =IFERROR(SUMIFS(F17:BE17,$F$7:$BE$7,"x")/COUNTIFS($F$7:$BE$7,"x",F17:BE17,">0"),"") | E17: =IF(D17="","",_xlfn.MINIFS(F17:BE17,$F$7:$BE$7,"x",F17:BE17,">0")) | F17: =IF($A17="","",IF(COUNTIFS(Måned!$A$5:$A$2000,$A17,Måned!$C$5:$C$2000,MONTH(F$5+3))=0,"",MAX(1,MIN(5,SUMIFS(Måned!$H$5:$H$2000,Måned!$A$5:$A$2000,$A17,Måned!$C$5:$C$2000,MONTH(F$5+3))+SUMPRODUCT((Vinduer!$A$5:$A$300=$A17)*Vinduer!$F$5:$F$300*(((Vinduer!$G$5:$G$300="")+(Vinduer!$G$5:$G$300=$B$2))>0)*((Vinduer!$C$5:$C$300<=Vinduer!$D$5:$D$300)*(F$4>=Vinduer!$C$5:$C$300)*(F$4<=Vinduer!$D$5:$D$300)+(Vinduer!$C$5:$C$300>Vinduer!$D$5:$D$300)*(((F$4>=Vinduer!$C$5:$C$300)+(F$4<=Vinduer!$D$5:$D$300))>0))))))) | G17: =IF($A17="","",IF(COUNTIFS(Måned!$A$5:$A$2000,$A17,Måned!$C$5:$C$2000,MONTH(G$5+3))=0,"",MAX(1,MIN(5,SUMIFS(Måned!$H$5:$H$2000,Måned!$A$5:$A$2000,$A17,Måned!$C$5:$C$2000,MONTH(G$5+3))+SUMPRODUCT((Vinduer!$A$5:$A$300=$A17)*Vinduer!$F$5:$F$300*(((Vinduer!$G$5:$G$300="")+(Vinduer!$G$5:$G$300=$B$2))>0)*((Vinduer!$C$5:$C$300<=Vinduer!$D$5:$D$300)*(G$4>=Vinduer!$C$5:$C$300)*(G$4<=Vinduer!$D$5:$D$300)+(Vinduer!$C$5:$C$300>Vinduer!$D$5:$D$300)*(((G$4>=Vinduer!$C$5:$C$300)+(G$4<=Vinduer!$D$5:$D$300))>0))))))) | H17: =IF($A17="","",IF(COUNTIFS(Måned!$A$5:$A$2000,$A17,Måned!$C$5:$C$2000,MONTH(H$5+3))=0,"",MAX(1,MIN(5,SUMIFS(Måned!$H$5:$H$2000,Måned!$A$5:$A$2000,$A17,Måned!$C$5:$C$2000,MONTH(H$5+3))+SUMPRODUCT((Vinduer!$A$5:$A$300=$A17)*Vinduer!$F$5:$F$300*(((Vinduer!$G$5:$G$300="")+(Vinduer!$G$5:$G$300=$B$2))>0)*((Vinduer!$C$5:$C$300<=Vinduer!$D$5:$D$300)*(H$4>=Vinduer!$C$5:$C$300)*(H$4<=Vinduer!$D$5:$D$300)+(Vinduer!$C$5:$C$300>Vinduer!$D$5:$D$300)*(((H$4>=Vinduer!$C$5:$C$300)+(H$4<=Vinduer!$D$5:$D$300))>0))))))) | I17: =IF($A17="","",IF(COUNTIFS(Måned!$A$5:$A$2000,$A17,Måned!$C$5:$C$2000,MONTH(I$5+3))=0,"",MAX(1,MIN(5,SUMIFS(Måned!$H$5:$H$2000,Måned!$A$5:$A$2000,$A17,Måned!$C$5:$C$2000,MONTH(I$5+3))+SUMPRODUCT((Vinduer!$A$5:$A$300=$A17)*Vinduer!$F$5:$F$300*(((Vinduer!$G$5:$G$300="")+(Vinduer!$G$5:$G$300=$B$2))>0)*((Vinduer!$C$5:$C$300<=Vinduer!$D$5:$D$300)*(I$4>=Vinduer!$C$5:$C$300)*(I$4<=Vinduer!$D$5:$D$300)+(Vinduer!$C$5:$C$300>Vinduer!$D$5:$D$300)*(((I$4>=Vinduer!$C$5:$C$300)+(I$4<=Vinduer!$D$5:$D$300))>0))))))) | J17: =IF($A17="","",IF(COUNTIFS(Måned!$A$5:$A$2000,$A17,Måned!$C$5:$C$2000,MONTH(J$5+3))=0,"",MAX(1,MIN(5,SUMIFS(Måned!$H$5:$H$2000,Måned!$A$5:$A$2000,$A17,Måned!$C$5:$C$2000,MONTH(J$5+3))+SUMPRODUCT((Vinduer!$A$5:$A$300=$A17)*Vinduer!$F$5:$F$300*(((Vinduer!$G$5:$G$300="")+(Vinduer!$G$5:$G$300=$B$2))>0)*((Vinduer!$C$5:$C$300<=Vinduer!$D$5:$D$300)*(J$4>=Vinduer!$C$5:$C$300)*(J$4<=Vinduer!$D$5:$D$300)+(Vinduer!$C$5:$C$300>Vinduer!$D$5:$D$300)*(((J$4>=Vinduer!$C$5:$C$300)+(J$4<=Vinduer!$D$5:$D$300))>0))))))) | K17: =IF($A17="","",IF(COUNTIFS(Måned!$A$5:$A$2000,$A17,Måned!$C$5:$C$2000,MONTH(K$5+3))=0,"",MAX(1,MIN(5,SUMIFS(Måned!$H$5:$H$2000,Måned!$A$5:$A$2000,$A17,Måned!$C$5:$C$2000,MONTH(K$5+3))+SUMPRODUCT((Vinduer!$A$5:$A$300=$A17)*Vinduer!$F$5:$F$300*(((Vinduer!$G$5:$G$300="")+(Vinduer!$G$5:$G$300=$B$2))>0)*((Vinduer!$C$5:$C$300<=Vinduer!$D$5:$D$300)*(K$4>=Vinduer!$C$5:$C$300)*(K$4<=Vinduer!$D$5:$D$300)+(Vinduer!$C$5:$C$300>Vinduer!$D$5:$D$300)*(((K$4>=Vinduer!$C$5:$C$300)+(K$4<=Vinduer!$D$5:$D$300))>0))))))) | L17: =IF($A17="","",IF(COUNTIFS(Måned!$A$5:$A$2000,$A17,Måned!$C$5:$C$2000,MONTH(L$5+3))=0,"",MAX(1,MIN(5,SUMIFS(Måned!$H$5:$H$2000,Måned!$A$5:$A$2000,$A17,Måned!$C$5:$C$2000,MONTH(L$5+3))+SUMPRODUCT((Vinduer!$A$5:$A$300=$A17)*Vinduer!$F$5:$F$300*(((Vinduer!$G$5:$G$300="")+(Vinduer!$G$5:$G$300=$B$2))>0)*((Vinduer!$C$5:$C$300<=Vinduer!$D$5:$D$300)*(L$4>=Vinduer!$C$5:$C$300)*(L$4<=Vinduer!$D$5:$D$300)+(Vinduer!$C$5:$C$300>Vinduer!$D$5:$D$300)*(((L$4>=Vinduer!$C$5:$C$300)+(L$4<=Vinduer!$D$5:$D$300))>0))))))) | M17: =IF($A17="","",IF(COUNTIFS(Måned!$A$5:$A$2000,$A17,Måned!$C$5:$C$2000,MONTH(M$5+3))=0,"",MAX(1,MIN(5,SUMIFS(Måned!$H$5:$H$2000,Måned!$A$5:$A$2000,$A17,Måned!$C$5:$C$2000,MONTH(M$5+3))+SUMPRODUCT((Vinduer!$A$5:$A$300=$A17)*Vinduer!$F$5:$F$300*(((Vinduer!$G$5:$G$300="")+(Vinduer!$G$5:$G$300=$B$2))>0)*((Vinduer!$C$5:$C$300<=Vinduer!$D$5:$D$300)*(M$4>=Vinduer!$C$5:$C$300)*(M$4<=Vinduer!$D$5:$D$300)+(Vinduer!$C$5:$C$300>Vinduer!$D$5:$D$300)*(((M$4>=Vinduer!$C$5:$C$300)+(M$4<=Vinduer!$D$5:$D$300))>0))))))) | ... BE17: =IF($A17="","",IF(COUNTIFS(Måned!$A$5:$A$2000,$A17,Måned!$C$5:$C$2000,MONTH(BE$5+3))=0,"",MAX(1,MIN(5,SUMIFS(Måned!$H$5:$H$2000,Måned!$A$5:$A$2000,$A17,Måned!$C$5:$C$2000,MONTH(BE$5+3))+SUMPRODUCT((Vinduer!$A$5:$A$300=$A17)*Vinduer!$F$5:$F$300*(((Vinduer!$G$5:$G$300="")+(Vinduer!$G$5:$G$300=$B$2))>0)*((Vinduer!$C$5:$C$300<=Vinduer!$D$5:$D$300)*(BE$4>=Vinduer!$C$5:$C$300)*(BE$4<=Vinduer!$D$5:$D$300)+(Vinduer!$C$5:$C$300>Vinduer!$D$5:$D$300)*(((BE$4>=Vinduer!$C$5:$C$300)+(BE$4<=Vinduer!$D$5:$D$300))>0)))))))
A18: =IF(Destinasjoner!A14="","",Destinasjoner!A14) | B18: =IF(A18="","",Destinasjoner!E14) | C18: =IF(A18="","",Destinasjoner!B14) | D18: =IFERROR(SUMIFS(F18:BE18,$F$7:$BE$7,"x")/COUNTIFS($F$7:$BE$7,"x",F18:BE18,">0"),"") | E18: =IF(D18="","",_xlfn.MINIFS(F18:BE18,$F$7:$BE$7,"x",F18:BE18,">0")) | F18: =IF($A18="","",IF(COUNTIFS(Måned!$A$5:$A$2000,$A18,Måned!$C$5:$C$2000,MONTH(F$5+3))=0,"",MAX(1,MIN(5,SUMIFS(Måned!$H$5:$H$2000,Måned!$A$5:$A$2000,$A18,Måned!$C$5:$C$2000,MONTH(F$5+3))+SUMPRODUCT((Vinduer!$A$5:$A$300=$A18)*Vinduer!$F$5:$F$300*(((Vinduer!$G$5:$G$300="")+(Vinduer!$G$5:$G$300=$B$2))>0)*((Vinduer!$C$5:$C$300<=Vinduer!$D$5:$D$300)*(F$4>=Vinduer!$C$5:$C$300)*(F$4<=Vinduer!$D$5:$D$300)+(Vinduer!$C$5:$C$300>Vinduer!$D$5:$D$300)*(((F$4>=Vinduer!$C$5:$C$300)+(F$4<=Vinduer!$D$5:$D$300))>0))))))) | G18: =IF($A18="","",IF(COUNTIFS(Måned!$A$5:$A$2000,$A18,Måned!$C$5:$C$2000,MONTH(G$5+3))=0,"",MAX(1,MIN(5,SUMIFS(Måned!$H$5:$H$2000,Måned!$A$5:$A$2000,$A18,Måned!$C$5:$C$2000,MONTH(G$5+3))+SUMPRODUCT((Vinduer!$A$5:$A$300=$A18)*Vinduer!$F$5:$F$300*(((Vinduer!$G$5:$G$300="")+(Vinduer!$G$5:$G$300=$B$2))>0)*((Vinduer!$C$5:$C$300<=Vinduer!$D$5:$D$300)*(G$4>=Vinduer!$C$5:$C$300)*(G$4<=Vinduer!$D$5:$D$300)+(Vinduer!$C$5:$C$300>Vinduer!$D$5:$D$300)*(((G$4>=Vinduer!$C$5:$C$300)+(G$4<=Vinduer!$D$5:$D$300))>0))))))) | H18: =IF($A18="","",IF(COUNTIFS(Måned!$A$5:$A$2000,$A18,Måned!$C$5:$C$2000,MONTH(H$5+3))=0,"",MAX(1,MIN(5,SUMIFS(Måned!$H$5:$H$2000,Måned!$A$5:$A$2000,$A18,Måned!$C$5:$C$2000,MONTH(H$5+3))+SUMPRODUCT((Vinduer!$A$5:$A$300=$A18)*Vinduer!$F$5:$F$300*(((Vinduer!$G$5:$G$300="")+(Vinduer!$G$5:$G$300=$B$2))>0)*((Vinduer!$C$5:$C$300<=Vinduer!$D$5:$D$300)*(H$4>=Vinduer!$C$5:$C$300)*(H$4<=Vinduer!$D$5:$D$300)+(Vinduer!$C$5:$C$300>Vinduer!$D$5:$D$300)*(((H$4>=Vinduer!$C$5:$C$300)+(H$4<=Vinduer!$D$5:$D$300))>0))))))) | I18: =IF($A18="","",IF(COUNTIFS(Måned!$A$5:$A$2000,$A18,Måned!$C$5:$C$2000,MONTH(I$5+3))=0,"",MAX(1,MIN(5,SUMIFS(Måned!$H$5:$H$2000,Måned!$A$5:$A$2000,$A18,Måned!$C$5:$C$2000,MONTH(I$5+3))+SUMPRODUCT((Vinduer!$A$5:$A$300=$A18)*Vinduer!$F$5:$F$300*(((Vinduer!$G$5:$G$300="")+(Vinduer!$G$5:$G$300=$B$2))>0)*((Vinduer!$C$5:$C$300<=Vinduer!$D$5:$D$300)*(I$4>=Vinduer!$C$5:$C$300)*(I$4<=Vinduer!$D$5:$D$300)+(Vinduer!$C$5:$C$300>Vinduer!$D$5:$D$300)*(((I$4>=Vinduer!$C$5:$C$300)+(I$4<=Vinduer!$D$5:$D$300))>0))))))) | J18: =IF($A18="","",IF(COUNTIFS(Måned!$A$5:$A$2000,$A18,Måned!$C$5:$C$2000,MONTH(J$5+3))=0,"",MAX(1,MIN(5,SUMIFS(Måned!$H$5:$H$2000,Måned!$A$5:$A$2000,$A18,Måned!$C$5:$C$2000,MONTH(J$5+3))+SUMPRODUCT((Vinduer!$A$5:$A$300=$A18)*Vinduer!$F$5:$F$300*(((Vinduer!$G$5:$G$300="")+(Vinduer!$G$5:$G$300=$B$2))>0)*((Vinduer!$C$5:$C$300<=Vinduer!$D$5:$D$300)*(J$4>=Vinduer!$C$5:$C$300)*(J$4<=Vinduer!$D$5:$D$300)+(Vinduer!$C$5:$C$300>Vinduer!$D$5:$D$300)*(((J$4>=Vinduer!$C$5:$C$300)+(J$4<=Vinduer!$D$5:$D$300))>0))))))) | K18: =IF($A18="","",IF(COUNTIFS(Måned!$A$5:$A$2000,$A18,Måned!$C$5:$C$2000,MONTH(K$5+3))=0,"",MAX(1,MIN(5,SUMIFS(Måned!$H$5:$H$2000,Måned!$A$5:$A$2000,$A18,Måned!$C$5:$C$2000,MONTH(K$5+3))+SUMPRODUCT((Vinduer!$A$5:$A$300=$A18)*Vinduer!$F$5:$F$300*(((Vinduer!$G$5:$G$300="")+(Vinduer!$G$5:$G$300=$B$2))>0)*((Vinduer!$C$5:$C$300<=Vinduer!$D$5:$D$300)*(K$4>=Vinduer!$C$5:$C$300)*(K$4<=Vinduer!$D$5:$D$300)+(Vinduer!$C$5:$C$300>Vinduer!$D$5:$D$300)*(((K$4>=Vinduer!$C$5:$C$300)+(K$4<=Vinduer!$D$5:$D$300))>0))))))) | L18: =IF($A18="","",IF(COUNTIFS(Måned!$A$5:$A$2000,$A18,Måned!$C$5:$C$2000,MONTH(L$5+3))=0,"",MAX(1,MIN(5,SUMIFS(Måned!$H$5:$H$2000,Måned!$A$5:$A$2000,$A18,Måned!$C$5:$C$2000,MONTH(L$5+3))+SUMPRODUCT((Vinduer!$A$5:$A$300=$A18)*Vinduer!$F$5:$F$300*(((Vinduer!$G$5:$G$300="")+(Vinduer!$G$5:$G$300=$B$2))>0)*((Vinduer!$C$5:$C$300<=Vinduer!$D$5:$D$300)*(L$4>=Vinduer!$C$5:$C$300)*(L$4<=Vinduer!$D$5:$D$300)+(Vinduer!$C$5:$C$300>Vinduer!$D$5:$D$300)*(((L$4>=Vinduer!$C$5:$C$300)+(L$4<=Vinduer!$D$5:$D$300))>0))))))) | M18: =IF($A18="","",IF(COUNTIFS(Måned!$A$5:$A$2000,$A18,Måned!$C$5:$C$2000,MONTH(M$5+3))=0,"",MAX(1,MIN(5,SUMIFS(Måned!$H$5:$H$2000,Måned!$A$5:$A$2000,$A18,Måned!$C$5:$C$2000,MONTH(M$5+3))+SUMPRODUCT((Vinduer!$A$5:$A$300=$A18)*Vinduer!$F$5:$F$300*(((Vinduer!$G$5:$G$300="")+(Vinduer!$G$5:$G$300=$B$2))>0)*((Vinduer!$C$5:$C$300<=Vinduer!$D$5:$D$300)*(M$4>=Vinduer!$C$5:$C$300)*(M$4<=Vinduer!$D$5:$D$300)+(Vinduer!$C$5:$C$300>Vinduer!$D$5:$D$300)*(((M$4>=Vinduer!$C$5:$C$300)+(M$4<=Vinduer!$D$5:$D$300))>0))))))) | ... BE18: =IF($A18="","",IF(COUNTIFS(Måned!$A$5:$A$2000,$A18,Måned!$C$5:$C$2000,MONTH(BE$5+3))=0,"",MAX(1,MIN(5,SUMIFS(Måned!$H$5:$H$2000,Måned!$A$5:$A$2000,$A18,Måned!$C$5:$C$2000,MONTH(BE$5+3))+SUMPRODUCT((Vinduer!$A$5:$A$300=$A18)*Vinduer!$F$5:$F$300*(((Vinduer!$G$5:$G$300="")+(Vinduer!$G$5:$G$300=$B$2))>0)*((Vinduer!$C$5:$C$300<=Vinduer!$D$5:$D$300)*(BE$4>=Vinduer!$C$5:$C$300)*(BE$4<=Vinduer!$D$5:$D$300)+(Vinduer!$C$5:$C$300>Vinduer!$D$5:$D$300)*(((BE$4>=Vinduer!$C$5:$C$300)+(BE$4<=Vinduer!$D$5:$D$300))>0)))))))
A19: =IF(Destinasjoner!A15="","",Destinasjoner!A15) | B19: =IF(A19="","",Destinasjoner!E15) | C19: =IF(A19="","",Destinasjoner!B15) | D19: =IFERROR(SUMIFS(F19:BE19,$F$7:$BE$7,"x")/COUNTIFS($F$7:$BE$7,"x",F19:BE19,">0"),"") | E19: =IF(D19="","",_xlfn.MINIFS(F19:BE19,$F$7:$BE$7,"x",F19:BE19,">0")) | F19: =IF($A19="","",IF(COUNTIFS(Måned!$A$5:$A$2000,$A19,Måned!$C$5:$C$2000,MONTH(F$5+3))=0,"",MAX(1,MIN(5,SUMIFS(Måned!$H$5:$H$2000,Måned!$A$5:$A$2000,$A19,Måned!$C$5:$C$2000,MONTH(F$5+3))+SUMPRODUCT((Vinduer!$A$5:$A$300=$A19)*Vinduer!$F$5:$F$300*(((Vinduer!$G$5:$G$300="")+(Vinduer!$G$5:$G$300=$B$2))>0)*((Vinduer!$C$5:$C$300<=Vinduer!$D$5:$D$300)*(F$4>=Vinduer!$C$5:$C$300)*(F$4<=Vinduer!$D$5:$D$300)+(Vinduer!$C$5:$C$300>Vinduer!$D$5:$D$300)*(((F$4>=Vinduer!$C$5:$C$300)+(F$4<=Vinduer!$D$5:$D$300))>0))))))) | G19: =IF($A19="","",IF(COUNTIFS(Måned!$A$5:$A$2000,$A19,Måned!$C$5:$C$2000,MONTH(G$5+3))=0,"",MAX(1,MIN(5,SUMIFS(Måned!$H$5:$H$2000,Måned!$A$5:$A$2000,$A19,Måned!$C$5:$C$2000,MONTH(G$5+3))+SUMPRODUCT((Vinduer!$A$5:$A$300=$A19)*Vinduer!$F$5:$F$300*(((Vinduer!$G$5:$G$300="")+(Vinduer!$G$5:$G$300=$B$2))>0)*((Vinduer!$C$5:$C$300<=Vinduer!$D$5:$D$300)*(G$4>=Vinduer!$C$5:$C$300)*(G$4<=Vinduer!$D$5:$D$300)+(Vinduer!$C$5:$C$300>Vinduer!$D$5:$D$300)*(((G$4>=Vinduer!$C$5:$C$300)+(G$4<=Vinduer!$D$5:$D$300))>0))))))) | H19: =IF($A19="","",IF(COUNTIFS(Måned!$A$5:$A$2000,$A19,Måned!$C$5:$C$2000,MONTH(H$5+3))=0,"",MAX(1,MIN(5,SUMIFS(Måned!$H$5:$H$2000,Måned!$A$5:$A$2000,$A19,Måned!$C$5:$C$2000,MONTH(H$5+3))+SUMPRODUCT((Vinduer!$A$5:$A$300=$A19)*Vinduer!$F$5:$F$300*(((Vinduer!$G$5:$G$300="")+(Vinduer!$G$5:$G$300=$B$2))>0)*((Vinduer!$C$5:$C$300<=Vinduer!$D$5:$D$300)*(H$4>=Vinduer!$C$5:$C$300)*(H$4<=Vinduer!$D$5:$D$300)+(Vinduer!$C$5:$C$300>Vinduer!$D$5:$D$300)*(((H$4>=Vinduer!$C$5:$C$300)+(H$4<=Vinduer!$D$5:$D$300))>0))))))) | I19: =IF($A19="","",IF(COUNTIFS(Måned!$A$5:$A$2000,$A19,Måned!$C$5:$C$2000,MONTH(I$5+3))=0,"",MAX(1,MIN(5,SUMIFS(Måned!$H$5:$H$2000,Måned!$A$5:$A$2000,$A19,Måned!$C$5:$C$2000,MONTH(I$5+3))+SUMPRODUCT((Vinduer!$A$5:$A$300=$A19)*Vinduer!$F$5:$F$300*(((Vinduer!$G$5:$G$300="")+(Vinduer!$G$5:$G$300=$B$2))>0)*((Vinduer!$C$5:$C$300<=Vinduer!$D$5:$D$300)*(I$4>=Vinduer!$C$5:$C$300)*(I$4<=Vinduer!$D$5:$D$300)+(Vinduer!$C$5:$C$300>Vinduer!$D$5:$D$300)*(((I$4>=Vinduer!$C$5:$C$300)+(I$4<=Vinduer!$D$5:$D$300))>0))))))) | J19: =IF($A19="","",IF(COUNTIFS(Måned!$A$5:$A$2000,$A19,Måned!$C$5:$C$2000,MONTH(J$5+3))=0,"",MAX(1,MIN(5,SUMIFS(Måned!$H$5:$H$2000,Måned!$A$5:$A$2000,$A19,Måned!$C$5:$C$2000,MONTH(J$5+3))+SUMPRODUCT((Vinduer!$A$5:$A$300=$A19)*Vinduer!$F$5:$F$300*(((Vinduer!$G$5:$G$300="")+(Vinduer!$G$5:$G$300=$B$2))>0)*((Vinduer!$C$5:$C$300<=Vinduer!$D$5:$D$300)*(J$4>=Vinduer!$C$5:$C$300)*(J$4<=Vinduer!$D$5:$D$300)+(Vinduer!$C$5:$C$300>Vinduer!$D$5:$D$300)*(((J$4>=Vinduer!$C$5:$C$300)+(J$4<=Vinduer!$D$5:$D$300))>0))))))) | K19: =IF($A19="","",IF(COUNTIFS(Måned!$A$5:$A$2000,$A19,Måned!$C$5:$C$2000,MONTH(K$5+3))=0,"",MAX(1,MIN(5,SUMIFS(Måned!$H$5:$H$2000,Måned!$A$5:$A$2000,$A19,Måned!$C$5:$C$2000,MONTH(K$5+3))+SUMPRODUCT((Vinduer!$A$5:$A$300=$A19)*Vinduer!$F$5:$F$300*(((Vinduer!$G$5:$G$300="")+(Vinduer!$G$5:$G$300=$B$2))>0)*((Vinduer!$C$5:$C$300<=Vinduer!$D$5:$D$300)*(K$4>=Vinduer!$C$5:$C$300)*(K$4<=Vinduer!$D$5:$D$300)+(Vinduer!$C$5:$C$300>Vinduer!$D$5:$D$300)*(((K$4>=Vinduer!$C$5:$C$300)+(K$4<=Vinduer!$D$5:$D$300))>0))))))) | L19: =IF($A19="","",IF(COUNTIFS(Måned!$A$5:$A$2000,$A19,Måned!$C$5:$C$2000,MONTH(L$5+3))=0,"",MAX(1,MIN(5,SUMIFS(Måned!$H$5:$H$2000,Måned!$A$5:$A$2000,$A19,Måned!$C$5:$C$2000,MONTH(L$5+3))+SUMPRODUCT((Vinduer!$A$5:$A$300=$A19)*Vinduer!$F$5:$F$300*(((Vinduer!$G$5:$G$300="")+(Vinduer!$G$5:$G$300=$B$2))>0)*((Vinduer!$C$5:$C$300<=Vinduer!$D$5:$D$300)*(L$4>=Vinduer!$C$5:$C$300)*(L$4<=Vinduer!$D$5:$D$300)+(Vinduer!$C$5:$C$300>Vinduer!$D$5:$D$300)*(((L$4>=Vinduer!$C$5:$C$300)+(L$4<=Vinduer!$D$5:$D$300))>0))))))) | M19: =IF($A19="","",IF(COUNTIFS(Måned!$A$5:$A$2000,$A19,Måned!$C$5:$C$2000,MONTH(M$5+3))=0,"",MAX(1,MIN(5,SUMIFS(Måned!$H$5:$H$2000,Måned!$A$5:$A$2000,$A19,Måned!$C$5:$C$2000,MONTH(M$5+3))+SUMPRODUCT((Vinduer!$A$5:$A$300=$A19)*Vinduer!$F$5:$F$300*(((Vinduer!$G$5:$G$300="")+(Vinduer!$G$5:$G$300=$B$2))>0)*((Vinduer!$C$5:$C$300<=Vinduer!$D$5:$D$300)*(M$4>=Vinduer!$C$5:$C$300)*(M$4<=Vinduer!$D$5:$D$300)+(Vinduer!$C$5:$C$300>Vinduer!$D$5:$D$300)*(((M$4>=Vinduer!$C$5:$C$300)+(M$4<=Vinduer!$D$5:$D$300))>0))))))) | ... BE19: =IF($A19="","",IF(COUNTIFS(Måned!$A$5:$A$2000,$A19,Måned!$C$5:$C$2000,MONTH(BE$5+3))=0,"",MAX(1,MIN(5,SUMIFS(Måned!$H$5:$H$2000,Måned!$A$5:$A$2000,$A19,Måned!$C$5:$C$2000,MONTH(BE$5+3))+SUMPRODUCT((Vinduer!$A$5:$A$300=$A19)*Vinduer!$F$5:$F$300*(((Vinduer!$G$5:$G$300="")+(Vinduer!$G$5:$G$300=$B$2))>0)*((Vinduer!$C$5:$C$300<=Vinduer!$D$5:$D$300)*(BE$4>=Vinduer!$C$5:$C$300)*(BE$4<=Vinduer!$D$5:$D$300)+(Vinduer!$C$5:$C$300>Vinduer!$D$5:$D$300)*(((BE$4>=Vinduer!$C$5:$C$300)+(BE$4<=Vinduer!$D$5:$D$300))>0)))))))
